Workbook

Sheet 说明
A1: 兼容旧版Excel（无VSTACK/UNIQUE/XLOOKUP），通过INDEX/MATCH与辅助表实现。
A2: 使用步骤：
A3: 1) 将本模板与 AQ_2020.xlsx … AQ_2024.xlsx 放在同一文件夹；各年度含工作表‘原始数据’（列：A银行 B贷款总额 C逾期 D不良 E关注 F新发生不良）。
A4: 2) 在‘汇总_兼容版’A列下拉选择银行名称（来自‘辅助’的合并清单），向下最多支持1000行；
A5: 3) 各年度列将自动用INDEX/MATCH从对应年度取数，并计算逾期率/不良率/关注率；
A6: 4) ‘趋势_兼容版’自动汇总合计并生成趋势图；
A7: 5) 若需更多行或更多年份，可在‘辅助’与‘汇总_兼容版’相应扩展行数/复制列组并调整年份与外链文件名。

Sheet 汇总_兼容版
B1: 贷款总额 | G1: 逾期 | L1: 不良 | Q1: 关注 | V1: 新发生不良 | AA1: 逾期率 | AF1: 不良率 | AK1: 关注率
A2: 银行 | B2: 2020 | C2: 2021 | D2: 2022 | E2: 2023 | F2: 2024 | G2: 2020 | H2: 2021 | I2: 2022 | J2: 2023 | K2: 2024 | L2: 2020 | M2: 2021 | N2: 2022 | O2: 2023 | P2: 2024 | Q2: 2020 | R2: 2021 | S2: 2022 | T2: 2023 | U2: 2024 | V2: 2020 | W2: 2021 | X2: 2022 | Y2: 2023 | Z2: 2024 | AA2: 2020 | AB2: 2021 | AC2: 2022 | AD2: 2023 | AE2: 2024 | AF2: 2020 | AG2: 2021 | AH2: 2022 | AI2: 2023 | AJ2: 2024 | AK2: 2020 | AL2: 2021 | AM2: 2022 | AN2: 2023 | AO2: 2024
B3: =IF($A3="","",IFERROR(INDEX('[AQ_2020.xlsx]原始数据'!$B:$B,MATCH($A3,'[AQ_2020.xlsx]原始数据'!$A:$A,0)),"")) | C3: =IF($A3="","",IFERROR(INDEX('[AQ_2021.xlsx]原始数据'!$B:$B,MATCH($A3,'[AQ_2021.xlsx]原始数据'!$A:$A,0)),"")) | D3: =IF($A3="","",IFERROR(INDEX('[AQ_2022.xlsx]原始数据'!$B:$B,MATCH($A3,'[AQ_2022.xlsx]原始数据'!$A:$A,0)),"")) | E3: =IF($A3="","",IFERROR(INDEX('[AQ_2023.xlsx]原始数据'!$B:$B,MATCH($A3,'[AQ_2023.xlsx]原始数据'!$A:$A,0)),"")) | F3: =IF($A3="","",IFERROR(INDEX('[AQ_2024.xlsx]原始数据'!$B:$B,MATCH($A3,'[AQ_2024.xlsx]原始数据'!$A:$A,0)),"")) | G3: =IF($A3="","",IFERROR(INDEX('[AQ_2020.xlsx]原始数据'!$C:$C,MATCH($A3,'[AQ_2020.xlsx]原始数据'!$A:$A,0)),"")) | H3: =IF($A3="","",IFERROR(INDEX('[AQ_2021.xlsx]原始数据'!$C:$C,MATCH($A3,'[AQ_2021.xlsx]原始数据'!$A:$A,0)),"")) | I3: =IF($A3="","",IFERROR(INDEX('[AQ_2022.xlsx]原始数据'!$C:$C,MATCH($A3,'[AQ_2022.xlsx]原始数据'!$A:$A,0)),"")) | J3: =IF($A3="","",IFERROR(INDEX('[AQ_2023.xlsx]原始数据'!$C:$C,MATCH($A3,'[AQ_2023.xlsx]原始数据'!$A:$A,0)),"")) | K3: =IF($A3="","",IFERROR(INDEX('[AQ_2024.xlsx]原始数据'!$C:$C,MATCH($A3,'[AQ_2024.xlsx]原始数据'!$A:$A,0)),"")) | L3: =IF($A3="","",IFERROR(INDEX('[AQ_2020.xlsx]原始数据'!$D:$D,MATCH($A3,'[AQ_2020.xlsx]原始数据'!$A:$A,0)),"")) | M3: =IF($A3="","",IFERROR(INDEX('[AQ_2021.xlsx]原始数据'!$D:$D,MATCH($A3,'[AQ_2021.xlsx]原始数据'!$A:$A,0)),"")) | N3: =IF($A3="","",IFERROR(INDEX('[AQ_2022.xlsx]原始数据'!$D:$D,MATCH($A3,'[AQ_2022.xlsx]原始数据'!$A:$A,0)),"")) | O3: =IF($A3="","",IFERROR(INDEX('[AQ_2023.xlsx]原始数据'!$D:$D,MATCH($A3,'[AQ_2023.xlsx]原始数据'!$A:$A,0)),"")) | P3: =IF($A3="","",IFERROR(INDEX('[AQ_2024.xlsx]原始数据'!$D:$D,MATCH($A3,'[AQ_2024.xlsx]原始数据'!$A:$A,0)),"")) | Q3: =IF($A3="","",IFERROR(INDEX('[AQ_2020.xlsx]原始数据'!$E:$E,MATCH($A3,'[AQ_2020.xlsx]原始数据'!$A:$A,0)),"")) | R3: =IF($A3="","",IFERROR(INDEX('[AQ_2021.xlsx]原始数据'!$E:$E,MATCH($A3,'[AQ_2021.xlsx]原始数据'!$A:$A,0)),"")) | S3: =IF($A3="","",IFERROR(INDEX('[AQ_2022.xlsx]原始数据'!$E:$E,MATCH($A3,'[AQ_2022.xlsx]原始数据'!$A:$A,0)),"")) | T3: =IF($A3="","",IFERROR(INDEX('[AQ_2023.xlsx]原始数据'!$E:$E,MATCH($A3,'[AQ_2023.xlsx]原始数据'!$A:$A,0)),"")) | U3: =IF($A3="","",IFERROR(INDEX('[AQ_2024.xlsx]原始数据'!$E:$E,MATCH($A3,'[AQ_2024.xlsx]原始数据'!$A:$A,0)),"")) | V3: =IF($A3="","",IFERROR(INDEX('[AQ_2020.xlsx]原始数据'!$F:$F,MATCH($A3,'[AQ_2020.xlsx]原始数据'!$A:$A,0)),"")) | W3: =IF($A3="","",IFERROR(INDEX('[AQ_2021.xlsx]原始数据'!$F:$F,MATCH($A3,'[AQ_2021.xlsx]原始数据'!$A:$A,0)),"")) | X3: =IF($A3="","",IFERROR(INDEX('[AQ_2022.xlsx]原始数据'!$F:$F,MATCH($A3,'[AQ_2022.xlsx]原始数据'!$A:$A,0)),"")) | Y3: =IF($A3="","",IFERROR(INDEX('[AQ_2023.xlsx]原始数据'!$F:$F,MATCH($A3,'[AQ_2023.xlsx]原始数据'!$A:$A,0)),"")) | Z3: =IF($A3="","",IFERROR(INDEX('[AQ_2024.xlsx]原始数据'!$F:$F,MATCH($A3,'[AQ_2024.xlsx]原始数据'!$A:$A,0)),"")) | AA3: =IFERROR(G3/B3,"") | AB3: =IFERROR(H3/C3,"") | AC3: =IFERROR(I3/D3,"") | AD3: =IFERROR(J3/E3,"") | AE3: =IFERROR(K3/F3,"") | AF3: =IFERROR(L3/B3,"") | AG3: =IFERROR(M3/C3,"") | AH3: =IFERROR(N3/D3,"") | AI3: =IFERROR(O3/E3,"") | AJ3: =IFERROR(P3/F3,"") | AK3: =IFERROR(Q3/B3,"") | AL3: =IFERROR(R3/C3,"") | AM3: =IFERROR(S3/D3,"") | AN3: =IFERROR(T3/E3,"") | AO3: =IFERROR(U3/F3,"")
B4: =IF($A4="","",IFERROR(INDEX('[AQ_2020.xlsx]原始数据'!$B:$B,MATCH($A4,'[AQ_2020.xlsx]原始数据'!$A:$A,0)),"")) | C4: =IF($A4="","",IFERROR(INDEX('[AQ_2021.xlsx]原始数据'!$B:$B,MATCH($A4,'[AQ_2021.xlsx]原始数据'!$A:$A,0)),"")) | D4: =IF($A4="","",IFERROR(INDEX('[AQ_2022.xlsx]原始数据'!$B:$B,MATCH($A4,'[AQ_2022.xlsx]原始数据'!$A:$A,0)),"")) | E4: =IF($A4="","",IFERROR(INDEX('[AQ_2023.xlsx]原始数据'!$B:$B,MATCH($A4,'[AQ_2023.xlsx]原始数据'!$A:$A,0)),"")) | F4: =IF($A4="","",IFERROR(INDEX('[AQ_2024.xlsx]原始数据'!$B:$B,MATCH($A4,'[AQ_2024.xlsx]原始数据'!$A:$A,0)),"")) | G4: =IF($A4="","",IFERROR(INDEX('[AQ_2020.xlsx]原始数据'!$C:$C,MATCH($A4,'[AQ_2020.xlsx]原始数据'!$A:$A,0)),"")) | H4: =IF($A4="","",IFERROR(INDEX('[AQ_2021.xlsx]原始数据'!$C:$C,MATCH($A4,'[AQ_2021.xlsx]原始数据'!$A:$A,0)),"")) | I4: =IF($A4="","",IFERROR(INDEX('[AQ_2022.xlsx]原始数据'!$C:$C,MATCH($A4,'[AQ_2022.xlsx]原始数据'!$A:$A,0)),"")) | J4: =IF($A4="","",IFERROR(INDEX('[AQ_2023.xlsx]原始数据'!$C:$C,MATCH($A4,'[AQ_2023.xlsx]原始数据'!$A:$A,0)),"")) | K4: =IF($A4="","",IFERROR(INDEX('[AQ_2024.xlsx]原始数据'!$C:$C,MATCH($A4,'[AQ_2024.xlsx]原始数据'!$A:$A,0)),"")) | L4: =IF($A4="","",IFERROR(INDEX('[AQ_2020.xlsx]原始数据'!$D:$D,MATCH($A4,'[AQ_2020.xlsx]原始数据'!$A:$A,0)),"")) | M4: =IF($A4="","",IFERROR(INDEX('[AQ_2021.xlsx]原始数据'!$D:$D,MATCH($A4,'[AQ_2021.xlsx]原始数据'!$A:$A,0)),"")) | N4: =IF($A4="","",IFERROR(INDEX('[AQ_2022.xlsx]原始数据'!$D:$D,MATCH($A4,'[AQ_2022.xlsx]原始数据'!$A:$A,0)),"")) | O4: =IF($A4="","",IFERROR(INDEX('[AQ_2023.xlsx]原始数据'!$D:$D,MATCH($A4,'[AQ_2023.xlsx]原始数据'!$A:$A,0)),"")) | P4: =IF($A4="","",IFERROR(INDEX('[AQ_2024.xlsx]原始数据'!$D:$D,MATCH($A4,'[AQ_2024.xlsx]原始数据'!$A:$A,0)),"")) | Q4: =IF($A4="","",IFERROR(INDEX('[AQ_2020.xlsx]原始数据'!$E:$E,MATCH($A4,'[AQ_2020.xlsx]原始数据'!$A:$A,0)),"")) | R4: =IF($A4="","",IFERROR(INDEX('[AQ_2021.xlsx]原始数据'!$E:$E,MATCH($A4,'[AQ_2021.xlsx]原始数据'!$A:$A,0)),"")) | S4: =IF($A4="","",IFERROR(INDEX('[AQ_2022.xlsx]原始数据'!$E:$E,MATCH($A4,'[AQ_2022.xlsx]原始数据'!$A:$A,0)),"")) | T4: =IF($A4="","",IFERROR(INDEX('[AQ_2023.xlsx]原始数据'!$E:$E,MATCH($A4,'[AQ_2023.xlsx]原始数据'!$A:$A,0)),"")) | U4: =IF($A4="","",IFERROR(INDEX('[AQ_2024.xlsx]原始数据'!$E:$E,MATCH($A4,'[AQ_2024.xlsx]原始数据'!$A:$A,0)),"")) | V4: =IF($A4="","",IFERROR(INDEX('[AQ_2020.xlsx]原始数据'!$F:$F,MATCH($A4,'[AQ_2020.xlsx]原始数据'!$A:$A,0)),"")) | W4: =IF($A4="","",IFERROR(INDEX('[AQ_2021.xlsx]原始数据'!$F:$F,MATCH($A4,'[AQ_2021.xlsx]原始数据'!$A:$A,0)),"")) | X4: =IF($A4="","",IFERROR(INDEX('[AQ_2022.xlsx]原始数据'!$F:$F,MATCH($A4,'[AQ_2022.xlsx]原始数据'!$A:$A,0)),"")) | Y4: =IF($A4="","",IFERROR(INDEX('[AQ_2023.xlsx]原始数据'!$F:$F,MATCH($A4,'[AQ_2023.xlsx]原始数据'!$A:$A,0)),"")) | Z4: =IF($A4="","",IFERROR(INDEX('[AQ_2024.xlsx]原始数据'!$F:$F,MATCH($A4,'[AQ_2024.xlsx]原始数据'!$A:$A,0)),"")) | AA4: =IFERROR(G4/B4,"") | AB4: =IFERROR(H4/C4,"") | AC4: =IFERROR(I4/D4,"") | AD4: =IFERROR(J4/E4,"") | AE4: =IFERROR(K4/F4,"") | AF4: =IFERROR(L4/B4,"") | AG4: =IFERROR(M4/C4,"") | AH4: =IFERROR(N4/D4,"") | AI4: =IFERROR(O4/E4,"") | AJ4: =IFERROR(P4/F4,"") | AK4: =IFERROR(Q4/B4,"") | AL4: =IFERROR(R4/C4,"") | AM4: =IFERROR(S4/D4,"") | AN4: =IFERROR(T4/E4,"") | AO4: =IFERROR(U4/F4,"")
B5: =IF($A5="","",IFERROR(INDEX('[AQ_2020.xlsx]原始数据'!$B:$B,MATCH($A5,'[AQ_2020.xlsx]原始数据'!$A:$A,0)),"")) | C5: =IF($A5="","",IFERROR(INDEX('[AQ_2021.xlsx]原始数据'!$B:$B,MATCH($A5,'[AQ_2021.xlsx]原始数据'!$A:$A,0)),"")) | D5: =IF($A5="","",IFERROR(INDEX('[AQ_2022.xlsx]原始数据'!$B:$B,MATCH($A5,'[AQ_2022.xlsx]原始数据'!$A:$A,0)),"")) | E5: =IF($A5="","",IFERROR(INDEX('[AQ_2023.xlsx]原始数据'!$B:$B,MATCH($A5,'[AQ_2023.xlsx]原始数据'!$A:$A,0)),"")) | F5: =IF($A5="","",IFERROR(INDEX('[AQ_2024.xlsx]原始数据'!$B:$B,MATCH($A5,'[AQ_2024.xlsx]原始数据'!$A:$A,0)),"")) | G5: =IF($A5="","",IFERROR(INDEX('[AQ_2020.xlsx]原始数据'!$C:$C,MATCH($A5,'[AQ_2020.xlsx]原始数据'!$A:$A,0)),"")) | H5: =IF($A5="","",IFERROR(INDEX('[AQ_2021.xlsx]原始数据'!$C:$C,MATCH($A5,'[AQ_2021.xlsx]原始数据'!$A:$A,0)),"")) | I5: =IF($A5="","",IFERROR(INDEX('[AQ_2022.xlsx]原始数据'!$C:$C,MATCH($A5,'[AQ_2022.xlsx]原始数据'!$A:$A,0)),"")) | J5: =IF($A5="","",IFERROR(INDEX('[AQ_2023.xlsx]原始数据'!$C:$C,MATCH($A5,'[AQ_2023.xlsx]原始数据'!$A:$A,0)),"")) | K5: =IF($A5="","",IFERROR(INDEX('[AQ_2024.xlsx]原始数据'!$C:$C,MATCH($A5,'[AQ_2024.xlsx]原始数据'!$A:$A,0)),"")) | L5: =IF($A5="","",IFERROR(INDEX('[AQ_2020.xlsx]原始数据'!$D:$D,MATCH($A5,'[AQ_2020.xlsx]原始数据'!$A:$A,0)),"")) | M5: =IF($A5="","",IFERROR(INDEX('[AQ_2021.xlsx]原始数据'!$D:$D,MATCH($A5,'[AQ_2021.xlsx]原始数据'!$A:$A,0)),"")) | N5: =IF($A5="","",IFERROR(INDEX('[AQ_2022.xlsx]原始数据'!$D:$D,MATCH($A5,'[AQ_2022.xlsx]原始数据'!$A:$A,0)),"")) | O5: =IF($A5="","",IFERROR(INDEX('[AQ_2023.xlsx]原始数据'!$D:$D,MATCH($A5,'[AQ_2023.xlsx]原始数据'!$A:$A,0)),"")) | P5: =IF($A5="","",IFERROR(INDEX('[AQ_2024.xlsx]原始数据'!$D:$D,MATCH($A5,'[AQ_2024.xlsx]原始数据'!$A:$A,0)),"")) | Q5: =IF($A5="","",IFERROR(INDEX('[AQ_2020.xlsx]原始数据'!$E:$E,MATCH($A5,'[AQ_2020.xlsx]原始数据'!$A:$A,0)),"")) | R5: =IF($A5="","",IFERROR(INDEX('[AQ_2021.xlsx]原始数据'!$E:$E,MATCH($A5,'[AQ_2021.xlsx]原始数据'!$A:$A,0)),"")) | S5: =IF($A5="","",IFERROR(INDEX('[AQ_2022.xlsx]原始数据'!$E:$E,MATCH($A5,'[AQ_2022.xlsx]原始数据'!$A:$A,0)),"")) | T5: =IF($A5="","",IFERROR(INDEX('[AQ_2023.xlsx]原始数据'!$E:$E,MATCH($A5,'[AQ_2023.xlsx]原始数据'!$A:$A,0)),"")) | U5: =IF($A5="","",IFERROR(INDEX('[AQ_2024.xlsx]原始数据'!$E:$E,MATCH($A5,'[AQ_2024.xlsx]原始数据'!$A:$A,0)),"")) | V5: =IF($A5="","",IFERROR(INDEX('[AQ_2020.xlsx]原始数据'!$F:$F,MATCH($A5,'[AQ_2020.xlsx]原始数据'!$A:$A,0)),"")) | W5: =IF($A5="","",IFERROR(INDEX('[AQ_2021.xlsx]原始数据'!$F:$F,MATCH($A5,'[AQ_2021.xlsx]原始数据'!$A:$A,0)),"")) | X5: =IF($A5="","",IFERROR(INDEX('[AQ_2022.xlsx]原始数据'!$F:$F,MATCH($A5,'[AQ_2022.xlsx]原始数据'!$A:$A,0)),"")) | Y5: =IF($A5="","",IFERROR(INDEX('[AQ_2023.xlsx]原始数据'!$F:$F,MATCH($A5,'[AQ_2023.xlsx]原始数据'!$A:$A,0)),"")) | Z5: =IF($A5="","",IFERROR(INDEX('[AQ_2024.xlsx]原始数据'!$F:$F,MATCH($A5,'[AQ_2024.xlsx]原始数据'!$A:$A,0)),"")) | AA5: =IFERROR(G5/B5,"") | AB5: =IFERROR(H5/C5,"") | AC5: =IFERROR(I5/D5,"") | AD5: =IFERROR(J5/E5,"") | AE5: =IFERROR(K5/F5,"") | AF5: =IFERROR(L5/B5,"") | AG5: =IFERROR(M5/C5,"") | AH5: =IFERROR(N5/D5,"") | AI5: =IFERROR(O5/E5,"") | AJ5: =IFERROR(P5/F5,"") | AK5: =IFERROR(Q5/B5,"") | AL5: =IFERROR(R5/C5,"") | AM5: =IFERROR(S5/D5,"") | AN5: =IFERROR(T5/E5,"") | AO5: =IFERROR(U5/F5,"")
B6: =IF($A6="","",IFERROR(INDEX('[AQ_2020.xlsx]原始数据'!$B:$B,MATCH($A6,'[AQ_2020.xlsx]原始数据'!$A:$A,0)),"")) | C6: =IF($A6="","",IFERROR(INDEX('[AQ_2021.xlsx]原始数据'!$B:$B,MATCH($A6,'[AQ_2021.xlsx]原始数据'!$A:$A,0)),"")) | D6: =IF($A6="","",IFERROR(INDEX('[AQ_2022.xlsx]原始数据'!$B:$B,MATCH($A6,'[AQ_2022.xlsx]原始数据'!$A:$A,0)),"")) | E6: =IF($A6="","",IFERROR(INDEX('[AQ_2023.xlsx]原始数据'!$B:$B,MATCH($A6,'[AQ_2023.xlsx]原始数据'!$A:$A,0)),"")) | F6: =IF($A6="","",IFERROR(INDEX('[AQ_2024.xlsx]原始数据'!$B:$B,MATCH($A6,'[AQ_2024.xlsx]原始数据'!$A:$A,0)),"")) | G6: =IF($A6="","",IFERROR(INDEX('[AQ_2020.xlsx]原始数据'!$C:$C,MATCH($A6,'[AQ_2020.xlsx]原始数据'!$A:$A,0)),"")) | H6: =IF($A6="","",IFERROR(INDEX('[AQ_2021.xlsx]原始数据'!$C:$C,MATCH($A6,'[AQ_2021.xlsx]原始数据'!$A:$A,0)),"")) | I6: =IF($A6="","",IFERROR(INDEX('[AQ_2022.xlsx]原始数据'!$C:$C,MATCH($A6,'[AQ_2022.xlsx]原始数据'!$A:$A,0)),"")) | J6: =IF($A6="","",IFERROR(INDEX('[AQ_2023.xlsx]原始数据'!$C:$C,MATCH($A6,'[AQ_2023.xlsx]原始数据'!$A:$A,0)),"")) | K6: =IF($A6="","",IFERROR(INDEX('[AQ_2024.xlsx]原始数据'!$C:$C,MATCH($A6,'[AQ_2024.xlsx]原始数据'!$A:$A,0)),"")) | L6: =IF($A6="","",IFERROR(INDEX('[AQ_2020.xlsx]原始数据'!$D:$D,MATCH($A6,'[AQ_2020.xlsx]原始数据'!$A:$A,0)),"")) | M6: =IF($A6="","",IFERROR(INDEX('[AQ_2021.xlsx]原始数据'!$D:$D,MATCH($A6,'[AQ_2021.xlsx]原始数据'!$A:$A,0)),"")) | N6: =IF($A6="","",IFERROR(INDEX('[AQ_2022.xlsx]原始数据'!$D:$D,MATCH($A6,'[AQ_2022.xlsx]原始数据'!$A:$A,0)),"")) | O6: =IF($A6="","",IFERROR(INDEX('[AQ_2023.xlsx]原始数据'!$D:$D,MATCH($A6,'[AQ_2023.xlsx]原始数据'!$A:$A,0)),"")) | P6: =IF($A6="","",IFERROR(INDEX('[AQ_2024.xlsx]原始数据'!$D:$D,MATCH($A6,'[AQ_2024.xlsx]原始数据'!$A:$A,0)),"")) | Q6: =IF($A6="","",IFERROR(INDEX('[AQ_2020.xlsx]原始数据'!$E:$E,MATCH($A6,'[AQ_2020.xlsx]原始数据'!$A:$A,0)),"")) | R6: =IF($A6="","",IFERROR(INDEX('[AQ_2021.xlsx]原始数据'!$E:$E,MATCH($A6,'[AQ_2021.xlsx]原始数据'!$A:$A,0)),"")) | S6: =IF($A6="","",IFERROR(INDEX('[AQ_2022.xlsx]原始数据'!$E:$E,MATCH($A6,'[AQ_2022.xlsx]原始数据'!$A:$A,0)),"")) | T6: =IF($A6="","",IFERROR(INDEX('[AQ_2023.xlsx]原始数据'!$E:$E,MATCH($A6,'[AQ_2023.xlsx]原始数据'!$A:$A,0)),"")) | U6: =IF($A6="","",IFERROR(INDEX('[AQ_2024.xlsx]原始数据'!$E:$E,MATCH($A6,'[AQ_2024.xlsx]原始数据'!$A:$A,0)),"")) | V6: =IF($A6="","",IFERROR(INDEX('[AQ_2020.xlsx]原始数据'!$F:$F,MATCH($A6,'[AQ_2020.xlsx]原始数据'!$A:$A,0)),"")) | W6: =IF($A6="","",IFERROR(INDEX('[AQ_2021.xlsx]原始数据'!$F:$F,MATCH($A6,'[AQ_2021.xlsx]原始数据'!$A:$A,0)),"")) | X6: =IF($A6="","",IFERROR(INDEX('[AQ_2022.xlsx]原始数据'!$F:$F,MATCH($A6,'[AQ_2022.xlsx]原始数据'!$A:$A,0)),"")) | Y6: =IF($A6="","",IFERROR(INDEX('[AQ_2023.xlsx]原始数据'!$F:$F,MATCH($A6,'[AQ_2023.xlsx]原始数据'!$A:$A,0)),"")) | Z6: =IF($A6="","",IFERROR(INDEX('[AQ_2024.xlsx]原始数据'!$F:$F,MATCH($A6,'[AQ_2024.xlsx]原始数据'!$A:$A,0)),"")) | AA6: =IFERROR(G6/B6,"") | AB6: =IFERROR(H6/C6,"") | AC6: =IFERROR(I6/D6,"") | AD6: =IFERROR(J6/E6,"") | AE6: =IFERROR(K6/F6,"") | AF6: =IFERROR(L6/B6,"") | AG6: =IFERROR(M6/C6,"") | AH6: =IFERROR(N6/D6,"") | AI6: =IFERROR(O6/E6,"") | AJ6: =IFERROR(P6/F6,"") | AK6: =IFERROR(Q6/B6,"") | AL6: =IFERROR(R6/C6,"") | AM6: =IFERROR(S6/D6,"") | AN6: =IFERROR(T6/E6,"") | AO6: =IFERROR(U6/F6,"")
B7: =IF($A7="","",IFERROR(INDEX('[AQ_2020.xlsx]原始数据'!$B:$B,MATCH($A7,'[AQ_2020.xlsx]原始数据'!$A:$A,0)),"")) | C7: =IF($A7="","",IFERROR(INDEX('[AQ_2021.xlsx]原始数据'!$B:$B,MATCH($A7,'[AQ_2021.xlsx]原始数据'!$A:$A,0)),"")) | D7: =IF($A7="","",IFERROR(INDEX('[AQ_2022.xlsx]原始数据'!$B:$B,MATCH($A7,'[AQ_2022.xlsx]原始数据'!$A:$A,0)),"")) | E7: =IF($A7="","",IFERROR(INDEX('[AQ_2023.xlsx]原始数据'!$B:$B,MATCH($A7,'[AQ_2023.xlsx]原始数据'!$A:$A,0)),"")) | F7: =IF($A7="","",IFERROR(INDEX('[AQ_2024.xlsx]原始数据'!$B:$B,MATCH($A7,'[AQ_2024.xlsx]原始数据'!$A:$A,0)),"")) | G7: =IF($A7="","",IFERROR(INDEX('[AQ_2020.xlsx]原始数据'!$C:$C,MATCH($A7,'[AQ_2020.xlsx]原始数据'!$A:$A,0)),"")) | H7: =IF($A7="","",IFERROR(INDEX('[AQ_2021.xlsx]原始数据'!$C:$C,MATCH($A7,'[AQ_2021.xlsx]原始数据'!$A:$A,0)),"")) | I7: =IF($A7="","",IFERROR(INDEX('[AQ_2022.xlsx]原始数据'!$C:$C,MATCH($A7,'[AQ_2022.xlsx]原始数据'!$A:$A,0)),"")) | J7: =IF($A7="","",IFERROR(INDEX('[AQ_2023.xlsx]原始数据'!$C:$C,MATCH($A7,'[AQ_2023.xlsx]原始数据'!$A:$A,0)),"")) | K7: =IF($A7="","",IFERROR(INDEX('[AQ_2024.xlsx]原始数据'!$C:$C,MATCH($A7,'[AQ_2024.xlsx]原始数据'!$A:$A,0)),"")) | L7: =IF($A7="","",IFERROR(INDEX('[AQ_2020.xlsx]原始数据'!$D:$D,MATCH($A7,'[AQ_2020.xlsx]原始数据'!$A:$A,0)),"")) | M7: =IF($A7="","",IFERROR(INDEX('[AQ_2021.xlsx]原始数据'!$D:$D,MATCH($A7,'[AQ_2021.xlsx]原始数据'!$A:$A,0)),"")) | N7: =IF($A7="","",IFERROR(INDEX('[AQ_2022.xlsx]原始数据'!$D:$D,MATCH($A7,'[AQ_2022.xlsx]原始数据'!$A:$A,0)),"")) | O7: =IF($A7="","",IFERROR(INDEX('[AQ_2023.xlsx]原始数据'!$D:$D,MATCH($A7,'[AQ_2023.xlsx]原始数据'!$A:$A,0)),"")) | P7: =IF($A7="","",IFERROR(INDEX('[AQ_2024.xlsx]原始数据'!$D:$D,MATCH($A7,'[AQ_2024.xlsx]原始数据'!$A:$A,0)),"")) | Q7: =IF($A7="","",IFERROR(INDEX('[AQ_2020.xlsx]原始数据'!$E:$E,MATCH($A7,'[AQ_2020.xlsx]原始数据'!$A:$A,0)),"")) | R7: =IF($A7="","",IFERROR(INDEX('[AQ_2021.xlsx]原始数据'!$E:$E,MATCH($A7,'[AQ_2021.xlsx]原始数据'!$A:$A,0)),"")) | S7: =IF($A7="","",IFERROR(INDEX('[AQ_2022.xlsx]原始数据'!$E:$E,MATCH($A7,'[AQ_2022.xlsx]原始数据'!$A:$A,0)),"")) | T7: =IF($A7="","",IFERROR(INDEX('[AQ_2023.xlsx]原始数据'!$E:$E,MATCH($A7,'[AQ_2023.xlsx]原始数据'!$A:$A,0)),"")) | U7: =IF($A7="","",IFERROR(INDEX('[AQ_2024.xlsx]原始数据'!$E:$E,MATCH($A7,'[AQ_2024.xlsx]原始数据'!$A:$A,0)),"")) | V7: =IF($A7="","",IFERROR(INDEX('[AQ_2020.xlsx]原始数据'!$F:$F,MATCH($A7,'[AQ_2020.xlsx]原始数据'!$A:$A,0)),"")) | W7: =IF($A7="","",IFERROR(INDEX('[AQ_2021.xlsx]原始数据'!$F:$F,MATCH($A7,'[AQ_2021.xlsx]原始数据'!$A:$A,0)),"")) | X7: =IF($A7="","",IFERROR(INDEX('[AQ_2022.xlsx]原始数据'!$F:$F,MATCH($A7,'[AQ_2022.xlsx]原始数据'!$A:$A,0)),"")) | Y7: =IF($A7="","",IFERROR(INDEX('[AQ_2023.xlsx]原始数据'!$F:$F,MATCH($A7,'[AQ_2023.xlsx]原始数据'!$A:$A,0)),"")) | Z7: =IF($A7="","",IFERROR(INDEX('[AQ_2024.xlsx]原始数据'!$F:$F,MATCH($A7,'[AQ_2024.xlsx]原始数据'!$A:$A,0)),"")) | AA7: =IFERROR(G7/B7,"") | AB7: =IFERROR(H7/C7,"") | AC7: =IFERROR(I7/D7,"") | AD7: =IFERROR(J7/E7,"") | AE7: =IFERROR(K7/F7,"") | AF7: =IFERROR(L7/B7,"") | AG7: =IFERROR(M7/C7,"") | AH7: =IFERROR(N7/D7,"") | AI7: =IFERROR(O7/E7,"") | AJ7: =IFERROR(P7/F7,"") | AK7: =IFERROR(Q7/B7,"") | AL7: =IFERROR(R7/C7,"") | AM7: =IFERROR(S7/D7,"") | AN7: =IFERROR(T7/E7,"") | AO7: =IFERROR(U7/F7,"")
B8: =IF($A8="","",IFERROR(INDEX('[AQ_2020.xlsx]原始数据'!$B:$B,MATCH($A8,'[AQ_2020.xlsx]原始数据'!$A:$A,0)),"")) | C8: =IF($A8="","",IFERROR(INDEX('[AQ_2021.xlsx]原始数据'!$B:$B,MATCH($A8,'[AQ_2021.xlsx]原始数据'!$A:$A,0)),"")) | D8: =IF($A8="","",IFERROR(INDEX('[AQ_2022.xlsx]原始数据'!$B:$B,MATCH($A8,'[AQ_2022.xlsx]原始数据'!$A:$A,0)),"")) | E8: =IF($A8="","",IFERROR(INDEX('[AQ_2023.xlsx]原始数据'!$B:$B,MATCH($A8,'[AQ_2023.xlsx]原始数据'!$A:$A,0)),"")) | F8: =IF($A8="","",IFERROR(INDEX('[AQ_2024.xlsx]原始数据'!$B:$B,MATCH($A8,'[AQ_2024.xlsx]原始数据'!$A:$A,0)),"")) | G8: =IF($A8="","",IFERROR(INDEX('[AQ_2020.xlsx]原始数据'!$C:$C,MATCH($A8,'[AQ_2020.xlsx]原始数据'!$A:$A,0)),"")) | H8: =IF($A8="","",IFERROR(INDEX('[AQ_2021.xlsx]原始数据'!$C:$C,MATCH($A8,'[AQ_2021.xlsx]原始数据'!$A:$A,0)),"")) | I8: =IF($A8="","",IFERROR(INDEX('[AQ_2022.xlsx]原始数据'!$C:$C,MATCH($A8,'[AQ_2022.xlsx]原始数据'!$A:$A,0)),"")) | J8: =IF($A8="","",IFERROR(INDEX('[AQ_2023.xlsx]原始数据'!$C:$C,MATCH($A8,'[AQ_2023.xlsx]原始数据'!$A:$A,0)),"")) | K8: =IF($A8="","",IFERROR(INDEX('[AQ_2024.xlsx]原始数据'!$C:$C,MATCH($A8,'[AQ_2024.xlsx]原始数据'!$A:$A,0)),"")) | L8: =IF($A8="","",IFERROR(INDEX('[AQ_2020.xlsx]原始数据'!$D:$D,MATCH($A8,'[AQ_2020.xlsx]原始数据'!$A:$A,0)),"")) | M8: =IF($A8="","",IFERROR(INDEX('[AQ_2021.xlsx]原始数据'!$D:$D,MATCH($A8,'[AQ_2021.xlsx]原始数据'!$A:$A,0)),"")) | N8: =IF($A8="","",IFERROR(INDEX('[AQ_2022.xlsx]原始数据'!$D:$D,MATCH($A8,'[AQ_2022.xlsx]原始数据'!$A:$A,0)),"")) | O8: =IF($A8="","",IFERROR(INDEX('[AQ_2023.xlsx]原始数据'!$D:$D,MATCH($A8,'[AQ_2023.xlsx]原始数据'!$A:$A,0)),"")) | P8: =IF($A8="","",IFERROR(INDEX('[AQ_2024.xlsx]原始数据'!$D:$D,MATCH($A8,'[AQ_2024.xlsx]原始数据'!$A:$A,0)),"")) | Q8: =IF($A8="","",IFERROR(INDEX('[AQ_2020.xlsx]原始数据'!$E:$E,MATCH($A8,'[AQ_2020.xlsx]原始数据'!$A:$A,0)),"")) | R8: =IF($A8="","",IFERROR(INDEX('[AQ_2021.xlsx]原始数据'!$E:$E,MATCH($A8,'[AQ_2021.xlsx]原始数据'!$A:$A,0)),"")) | S8: =IF($A8="","",IFERROR(INDEX('[AQ_2022.xlsx]原始数据'!$E:$E,MATCH($A8,'[AQ_2022.xlsx]原始数据'!$A:$A,0)),"")) | T8: =IF($A8="","",IFERROR(INDEX('[AQ_2023.xlsx]原始数据'!$E:$E,MATCH($A8,'[AQ_2023.xlsx]原始数据'!$A:$A,0)),"")) | U8: =IF($A8="","",IFERROR(INDEX('[AQ_2024.xlsx]原始数据'!$E:$E,MATCH($A8,'[AQ_2024.xlsx]原始数据'!$A:$A,0)),"")) | V8: =IF($A8="","",IFERROR(INDEX('[AQ_2020.xlsx]原始数据'!$F:$F,MATCH($A8,'[AQ_2020.xlsx]原始数据'!$A:$A,0)),"")) | W8: =IF($A8="","",IFERROR(INDEX('[AQ_2021.xlsx]原始数据'!$F:$F,MATCH($A8,'[AQ_2021.xlsx]原始数据'!$A:$A,0)),"")) | X8: =IF($A8="","",IFERROR(INDEX('[AQ_2022.xlsx]原始数据'!$F:$F,MATCH($A8,'[AQ_2022.xlsx]原始数据'!$A:$A,0)),"")) | Y8: =IF($A8="","",IFERROR(INDEX('[AQ_2023.xlsx]原始数据'!$F:$F,MATCH($A8,'[AQ_2023.xlsx]原始数据'!$A:$A,0)),"")) | Z8: =IF($A8="","",IFERROR(INDEX('[AQ_2024.xlsx]原始数据'!$F:$F,MATCH($A8,'[AQ_2024.xlsx]原始数据'!$A:$A,0)),"")) | AA8: =IFERROR(G8/B8,"") | AB8: =IFERROR(H8/C8,"") | AC8: =IFERROR(I8/D8,"") | AD8: =IFERROR(J8/E8,"") | AE8: =IFERROR(K8/F8,"") | AF8: =IFERROR(L8/B8,"") | AG8: =IFERROR(M8/C8,"") | AH8: =IFERROR(N8/D8,"") | AI8: =IFERROR(O8/E8,"") | AJ8: =IFERROR(P8/F8,"") | AK8: =IFERROR(Q8/B8,"") | AL8: =IFERROR(R8/C8,"") | AM8: =IFERROR(S8/D8,"") | AN8: =IFERROR(T8/E8,"") | AO8: =IFERROR(U8/F8,"")
B9: =IF($A9="","",IFERROR(INDEX('[AQ_2020.xlsx]原始数据'!$B:$B,MATCH($A9,'[AQ_2020.xlsx]原始数据'!$A:$A,0)),"")) | C9: =IF($A9="","",IFERROR(INDEX('[AQ_2021.xlsx]原始数据'!$B:$B,MATCH($A9,'[AQ_2021.xlsx]原始数据'!$A:$A,0)),"")) | D9: =IF($A9="","",IFERROR(INDEX('[AQ_2022.xlsx]原始数据'!$B:$B,MATCH($A9,'[AQ_2022.xlsx]原始数据'!$A:$A,0)),"")) | E9: =IF($A9="","",IFERROR(INDEX('[AQ_2023.xlsx]原始数据'!$B:$B,MATCH($A9,'[AQ_2023.xlsx]原始数据'!$A:$A,0)),"")) | F9: =IF($A9="","",IFERROR(INDEX('[AQ_2024.xlsx]原始数据'!$B:$B,MATCH($A9,'[AQ_2024.xlsx]原始数据'!$A:$A,0)),"")) | G9: =IF($A9="","",IFERROR(INDEX('[AQ_2020.xlsx]原始数据'!$C:$C,MATCH($A9,'[AQ_2020.xlsx]原始数据'!$A:$A,0)),"")) | H9: =IF($A9="","",IFERROR(INDEX('[AQ_2021.xlsx]原始数据'!$C:$C,MATCH($A9,'[AQ_2021.xlsx]原始数据'!$A:$A,0)),"")) | I9: =IF($A9="","",IFERROR(INDEX('[AQ_2022.xlsx]原始数据'!$C:$C,MATCH($A9,'[AQ_2022.xlsx]原始数据'!$A:$A,0)),"")) | J9: =IF($A9="","",IFERROR(INDEX('[AQ_2023.xlsx]原始数据'!$C:$C,MATCH($A9,'[AQ_2023.xlsx]原始数据'!$A:$A,0)),"")) | K9: =IF($A9="","",IFERROR(INDEX('[AQ_2024.xlsx]原始数据'!$C:$C,MATCH($A9,'[AQ_2024.xlsx]原始数据'!$A:$A,0)),"")) | L9: =IF($A9="","",IFERROR(INDEX('[AQ_2020.xlsx]原始数据'!$D:$D,MATCH($A9,'[AQ_2020.xlsx]原始数据'!$A:$A,0)),"")) | M9: =IF($A9="","",IFERROR(INDEX('[AQ_2021.xlsx]原始数据'!$D:$D,MATCH($A9,'[AQ_2021.xlsx]原始数据'!$A:$A,0)),"")) | N9: =IF($A9="","",IFERROR(INDEX('[AQ_2022.xlsx]原始数据'!$D:$D,MATCH($A9,'[AQ_2022.xlsx]原始数据'!$A:$A,0)),"")) | O9: =IF($A9="","",IFERROR(INDEX('[AQ_2023.xlsx]原始数据'!$D:$D,MATCH($A9,'[AQ_2023.xlsx]原始数据'!$A:$A,0)),"")) | P9: =IF($A9="","",IFERROR(INDEX('[AQ_2024.xlsx]原始数据'!$D:$D,MATCH($A9,'[AQ_2024.xlsx]原始数据'!$A:$A,0)),"")) | Q9: =IF($A9="","",IFERROR(INDEX('[AQ_2020.xlsx]原始数据'!$E:$E,MATCH($A9,'[AQ_2020.xlsx]原始数据'!$A:$A,0)),"")) | R9: =IF($A9="","",IFERROR(INDEX('[AQ_2021.xlsx]原始数据'!$E:$E,MATCH($A9,'[AQ_2021.xlsx]原始数据'!$A:$A,0)),"")) | S9: =IF($A9="","",IFERROR(INDEX('[AQ_2022.xlsx]原始数据'!$E:$E,MATCH($A9,'[AQ_2022.xlsx]原始数据'!$A:$A,0)),"")) | T9: =IF($A9="","",IFERROR(INDEX('[AQ_2023.xlsx]原始数据'!$E:$E,MATCH($A9,'[AQ_2023.xlsx]原始数据'!$A:$A,0)),"")) | U9: =IF($A9="","",IFERROR(INDEX('[AQ_2024.xlsx]原始数据'!$E:$E,MATCH($A9,'[AQ_2024.xlsx]原始数据'!$A:$A,0)),"")) | V9: =IF($A9="","",IFERROR(INDEX('[AQ_2020.xlsx]原始数据'!$F:$F,MATCH($A9,'[AQ_2020.xlsx]原始数据'!$A:$A,0)),"")) | W9: =IF($A9="","",IFERROR(INDEX('[AQ_2021.xlsx]原始数据'!$F:$F,MATCH($A9,'[AQ_2021.xlsx]原始数据'!$A:$A,0)),"")) | X9: =IF($A9="","",IFERROR(INDEX('[AQ_2022.xlsx]原始数据'!$F:$F,MATCH($A9,'[AQ_2022.xlsx]原始数据'!$A:$A,0)),"")) | Y9: =IF($A9="","",IFERROR(INDEX('[AQ_2023.xlsx]原始数据'!$F:$F,MATCH($A9,'[AQ_2023.xlsx]原始数据'!$A:$A,0)),"")) | Z9: =IF($A9="","",IFERROR(INDEX('[AQ_2024.xlsx]原始数据'!$F:$F,MATCH($A9,'[AQ_2024.xlsx]原始数据'!$A:$A,0)),"")) | AA9: =IFERROR(G9/B9,"") | AB9: =IFERROR(H9/C9,"") | AC9: =IFERROR(I9/D9,"") | AD9: =IFERROR(J9/E9,"") | AE9: =IFERROR(K9/F9,"") | AF9: =IFERROR(L9/B9,"") | AG9: =IFERROR(M9/C9,"") | AH9: =IFERROR(N9/D9,"") | AI9: =IFERROR(O9/E9,"") | AJ9: =IFERROR(P9/F9,"") | AK9: =IFERROR(Q9/B9,"") | AL9: =IFERROR(R9/C9,"") | AM9: =IFERROR(S9/D9,"") | AN9: =IFERROR(T9/E9,"") | AO9: =IFERROR(U9/F9,"")
B10: =IF($A10="","",IFERROR(INDEX('[AQ_2020.xlsx]原始数据'!$B:$B,MATCH($A10,'[AQ_2020.xlsx]原始数据'!$A:$A,0)),"")) | C10: =IF($A10="","",IFERROR(INDEX('[AQ_2021.xlsx]原始数据'!$B:$B,MATCH($A10,'[AQ_2021.xlsx]原始数据'!$A:$A,0)),"")) | D10: =IF($A10="","",IFERROR(INDEX('[AQ_2022.xlsx]原始数据'!$B:$B,MATCH($A10,'[AQ_2022.xlsx]原始数据'!$A:$A,0)),"")) | E10: =IF($A10="","",IFERROR(INDEX('[AQ_2023.xlsx]原始数据'!$B:$B,MATCH($A10,'[AQ_2023.xlsx]原始数据'!$A:$A,0)),"")) | F10: =IF($A10="","",IFERROR(INDEX('[AQ_2024.xlsx]原始数据'!$B:$B,MATCH($A10,'[AQ_2024.xlsx]原始数据'!$A:$A,0)),"")) | G10: =IF($A10="","",IFERROR(INDEX('[AQ_2020.xlsx]原始数据'!$C:$C,MATCH($A10,'[AQ_2020.xlsx]原始数据'!$A:$A,0)),"")) | H10: =IF($A10="","",IFERROR(INDEX('[AQ_2021.xlsx]原始数据'!$C:$C,MATCH($A10,'[AQ_2021.xlsx]原始数据'!$A:$A,0)),"")) | I10: =IF($A10="","",IFERROR(INDEX('[AQ_2022.xlsx]原始数据'!$C:$C,MATCH($A10,'[AQ_2022.xlsx]原始数据'!$A:$A,0)),"")) | J10: =IF($A10="","",IFERROR(INDEX('[AQ_2023.xlsx]原始数据'!$C:$C,MATCH($A10,'[AQ_2023.xlsx]原始数据'!$A:$A,0)),"")) | K10: =IF($A10="","",IFERROR(INDEX('[AQ_2024.xlsx]原始数据'!$C:$C,MATCH($A10,'[AQ_2024.xlsx]原始数据'!$A:$A,0)),"")) | L10: =IF($A10="","",IFERROR(INDEX('[AQ_2020.xlsx]原始数据'!$D:$D,MATCH($A10,'[AQ_2020.xlsx]原始数据'!$A:$A,0)),"")) | M10: =IF($A10="","",IFERROR(INDEX('[AQ_2021.xlsx]原始数据'!$D:$D,MATCH($A10,'[AQ_2021.xlsx]原始数据'!$A:$A,0)),"")) | N10: =IF($A10="","",IFERROR(INDEX('[AQ_2022.xlsx]原始数据'!$D:$D,MATCH($A10,'[AQ_2022.xlsx]原始数据'!$A:$A,0)),"")) | O10: =IF($A10="","",IFERROR(INDEX('[AQ_2023.xlsx]原始数据'!$D:$D,MATCH($A10,'[AQ_2023.xlsx]原始数据'!$A:$A,0)),"")) | P10: =IF($A10="","",IFERROR(INDEX('[AQ_2024.xlsx]原始数据'!$D:$D,MATCH($A10,'[AQ_2024.xlsx]原始数据'!$A:$A,0)),"")) | Q10: =IF($A10="","",IFERROR(INDEX('[AQ_2020.xlsx]原始数据'!$E:$E,MATCH($A10,'[AQ_2020.xlsx]原始数据'!$A:$A,0)),"")) | R10: =IF($A10="","",IFERROR(INDEX('[AQ_2021.xlsx]原始数据'!$E:$E,MATCH($A10,'[AQ_2021.xlsx]原始数据'!$A:$A,0)),"")) | S10: =IF($A10="","",IFERROR(INDEX('[AQ_2022.xlsx]原始数据'!$E:$E,MATCH($A10,'[AQ_2022.xlsx]原始数据'!$A:$A,0)),"")) | T10: =IF($A10="","",IFERROR(INDEX('[AQ_2023.xlsx]原始数据'!$E:$E,MATCH($A10,'[AQ_2023.xlsx]原始数据'!$A:$A,0)),"")) | U10: =IF($A10="","",IFERROR(INDEX('[AQ_2024.xlsx]原始数据'!$E:$E,MATCH($A10,'[AQ_2024.xlsx]原始数据'!$A:$A,0)),"")) | V10: =IF($A10="","",IFERROR(INDEX('[AQ_2020.xlsx]原始数据'!$F:$F,MATCH($A10,'[AQ_2020.xlsx]原始数据'!$A:$A,0)),"")) | W10: =IF($A10="","",IFERROR(INDEX('[AQ_2021.xlsx]原始数据'!$F:$F,MATCH($A10,'[AQ_2021.xlsx]原始数据'!$A:$A,0)),"")) | X10: =IF($A10="","",IFERROR(INDEX('[AQ_2022.xlsx]原始数据'!$F:$F,MATCH($A10,'[AQ_2022.xlsx]原始数据'!$A:$A,0)),"")) | Y10: =IF($A10="","",IFERROR(INDEX('[AQ_2023.xlsx]原始数据'!$F:$F,MATCH($A10,'[AQ_2023.xlsx]原始数据'!$A:$A,0)),"")) | Z10: =IF($A10="","",IFERROR(INDEX('[AQ_2024.xlsx]原始数据'!$F:$F,MATCH($A10,'[AQ_2024.xlsx]原始数据'!$A:$A,0)),"")) | AA10: =IFERROR(G10/B10,"") | AB10: =IFERROR(H10/C10,"") | AC10: =IFERROR(I10/D10,"") | AD10: =IFERROR(J10/E10,"") | AE10: =IFERROR(K10/F10,"") | AF10: =IFERROR(L10/B10,"") | AG10: =IFERROR(M10/C10,"") | AH10: =IFERROR(N10/D10,"") | AI10: =IFERROR(O10/E10,"") | AJ10: =IFERROR(P10/F10,"") | AK10: =IFERROR(Q10/B10,"") | AL10: =IFERROR(R10/C10,"") | AM10: =IFERROR(S10/D10,"") | AN10: =IFERROR(T10/E10,"") | AO10: =IFERROR(U10/F10,"")
B11: =IF($A11="","",IFERROR(INDEX('[AQ_2020.xlsx]原始数据'!$B:$B,MATCH($A11,'[AQ_2020.xlsx]原始数据'!$A:$A,0)),"")) | C11: =IF($A11="","",IFERROR(INDEX('[AQ_2021.xlsx]原始数据'!$B:$B,MATCH($A11,'[AQ_2021.xlsx]原始数据'!$A:$A,0)),"")) | D11: =IF($A11="","",IFERROR(INDEX('[AQ_2022.xlsx]原始数据'!$B:$B,MATCH($A11,'[AQ_2022.xlsx]原始数据'!$A:$A,0)),"")) | E11: =IF($A11="","",IFERROR(INDEX('[AQ_2023.xlsx]原始数据'!$B:$B,MATCH($A11,'[AQ_2023.xlsx]原始数据'!$A:$A,0)),"")) | F11: =IF($A11="","",IFERROR(INDEX('[AQ_2024.xlsx]原始数据'!$B:$B,MATCH($A11,'[AQ_2024.xlsx]原始数据'!$A:$A,0)),"")) | G11: =IF($A11="","",IFERROR(INDEX('[AQ_2020.xlsx]原始数据'!$C:$C,MATCH($A11,'[AQ_2020.xlsx]原始数据'!$A:$A,0)),"")) | H11: =IF($A11="","",IFERROR(INDEX('[AQ_2021.xlsx]原始数据'!$C:$C,MATCH($A11,'[AQ_2021.xlsx]原始数据'!$A:$A,0)),"")) | I11: =IF($A11="","",IFERROR(INDEX('[AQ_2022.xlsx]原始数据'!$C:$C,MATCH($A11,'[AQ_2022.xlsx]原始数据'!$A:$A,0)),"")) | J11: =IF($A11="","",IFERROR(INDEX('[AQ_2023.xlsx]原始数据'!$C:$C,MATCH($A11,'[AQ_2023.xlsx]原始数据'!$A:$A,0)),"")) | K11: =IF($A11="","",IFERROR(INDEX('[AQ_2024.xlsx]原始数据'!$C:$C,MATCH($A11,'[AQ_2024.xlsx]原始数据'!$A:$A,0)),"")) | L11: =IF($A11="","",IFERROR(INDEX('[AQ_2020.xlsx]原始数据'!$D:$D,MATCH($A11,'[AQ_2020.xlsx]原始数据'!$A:$A,0)),"")) | M11: =IF($A11="","",IFERROR(INDEX('[AQ_2021.xlsx]原始数据'!$D:$D,MATCH($A11,'[AQ_2021.xlsx]原始数据'!$A:$A,0)),"")) | N11: =IF($A11="","",IFERROR(INDEX('[AQ_2022.xlsx]原始数据'!$D:$D,MATCH($A11,'[AQ_2022.xlsx]原始数据'!$A:$A,0)),"")) | O11: =IF($A11="","",IFERROR(INDEX('[AQ_2023.xlsx]原始数据'!$D:$D,MATCH($A11,'[AQ_2023.xlsx]原始数据'!$A:$A,0)),"")) | P11: =IF($A11="","",IFERROR(INDEX('[AQ_2024.xlsx]原始数据'!$D:$D,MATCH($A11,'[AQ_2024.xlsx]原始数据'!$A:$A,0)),"")) | Q11: =IF($A11="","",IFERROR(INDEX('[AQ_2020.xlsx]原始数据'!$E:$E,MATCH($A11,'[AQ_2020.xlsx]原始数据'!$A:$A,0)),"")) | R11: =IF($A11="","",IFERROR(INDEX('[AQ_2021.xlsx]原始数据'!$E:$E,MATCH($A11,'[AQ_2021.xlsx]原始数据'!$A:$A,0)),"")) | S11: =IF($A11="","",IFERROR(INDEX('[AQ_2022.xlsx]原始数据'!$E:$E,MATCH($A11,'[AQ_2022.xlsx]原始数据'!$A:$A,0)),"")) | T11: =IF($A11="","",IFERROR(INDEX('[AQ_2023.xlsx]原始数据'!$E:$E,MATCH($A11,'[AQ_2023.xlsx]原始数据'!$A:$A,0)),"")) | U11: =IF($A11="","",IFERROR(INDEX('[AQ_2024.xlsx]原始数据'!$E:$E,MATCH($A11,'[AQ_2024.xlsx]原始数据'!$A:$A,0)),"")) | V11: =IF($A11="","",IFERROR(INDEX('[AQ_2020.xlsx]原始数据'!$F:$F,MATCH($A11,'[AQ_2020.xlsx]原始数据'!$A:$A,0)),"")) | W11: =IF($A11="","",IFERROR(INDEX('[AQ_2021.xlsx]原始数据'!$F:$F,MATCH($A11,'[AQ_2021.xlsx]原始数据'!$A:$A,0)),"")) | X11: =IF($A11="","",IFERROR(INDEX('[AQ_2022.xlsx]原始数据'!$F:$F,MATCH($A11,'[AQ_2022.xlsx]原始数据'!$A:$A,0)),"")) | Y11: =IF($A11="","",IFERROR(INDEX('[AQ_2023.xlsx]原始数据'!$F:$F,MATCH($A11,'[AQ_2023.xlsx]原始数据'!$A:$A,0)),"")) | Z11: =IF($A11="","",IFERROR(INDEX('[AQ_2024.xlsx]原始数据'!$F:$F,MATCH($A11,'[AQ_2024.xlsx]原始数据'!$A:$A,0)),"")) | AA11: =IFERROR(G11/B11,"") | AB11: =IFERROR(H11/C11,"") | AC11: =IFERROR(I11/D11,"") | AD11: =IFERROR(J11/E11,"") | AE11: =IFERROR(K11/F11,"") | AF11: =IFERROR(L11/B11,"") | AG11: =IFERROR(M11/C11,"") | AH11: =IFERROR(N11/D11,"") | AI11: =IFERROR(O11/E11,"") | AJ11: =IFERROR(P11/F11,"") | AK11: =IFERROR(Q11/B11,"") | AL11: =IFERROR(R11/C11,"") | AM11: =IFERROR(S11/D11,"") | AN11: =IFERROR(T11/E11,"") | AO11: =IFERROR(U11/F11,"")
B12: =IF($A12="","",IFERROR(INDEX('[AQ_2020.xlsx]原始数据'!$B:$B,MATCH($A12,'[AQ_2020.xlsx]原始数据'!$A:$A,0)),"")) | C12: =IF($A12="","",IFERROR(INDEX('[AQ_2021.xlsx]原始数据'!$B:$B,MATCH($A12,'[AQ_2021.xlsx]原始数据'!$A:$A,0)),"")) | D12: =IF($A12="","",IFERROR(INDEX('[AQ_2022.xlsx]原始数据'!$B:$B,MATCH($A12,'[AQ_2022.xlsx]原始数据'!$A:$A,0)),"")) | E12: =IF($A12="","",IFERROR(INDEX('[AQ_2023.xlsx]原始数据'!$B:$B,MATCH($A12,'[AQ_2023.xlsx]原始数据'!$A:$A,0)),"")) | F12: =IF($A12="","",IFERROR(INDEX('[AQ_2024.xlsx]原始数据'!$B:$B,MATCH($A12,'[AQ_2024.xlsx]原始数据'!$A:$A,0)),"")) | G12: =IF($A12="","",IFERROR(INDEX('[AQ_2020.xlsx]原始数据'!$C:$C,MATCH($A12,'[AQ_2020.xlsx]原始数据'!$A:$A,0)),"")) | H12: =IF($A12="","",IFERROR(INDEX('[AQ_2021.xlsx]原始数据'!$C:$C,MATCH($A12,'[AQ_2021.xlsx]原始数据'!$A:$A,0)),"")) | I12: =IF($A12="","",IFERROR(INDEX('[AQ_2022.xlsx]原始数据'!$C:$C,MATCH($A12,'[AQ_2022.xlsx]原始数据'!$A:$A,0)),"")) | J12: =IF($A12="","",IFERROR(INDEX('[AQ_2023.xlsx]原始数据'!$C:$C,MATCH($A12,'[AQ_2023.xlsx]原始数据'!$A:$A,0)),"")) | K12: =IF($A12="","",IFERROR(INDEX('[AQ_2024.xlsx]原始数据'!$C:$C,MATCH($A12,'[AQ_2024.xlsx]原始数据'!$A:$A,0)),"")) | L12: =IF($A12="","",IFERROR(INDEX('[AQ_2020.xlsx]原始数据'!$D:$D,MATCH($A12,'[AQ_2020.xlsx]原始数据'!$A:$A,0)),"")) | M12: =IF($A12="","",IFERROR(INDEX('[AQ_2021.xlsx]原始数据'!$D:$D,MATCH($A12,'[AQ_2021.xlsx]原始数据'!$A:$A,0)),"")) | N12: =IF($A12="","",IFERROR(INDEX('[AQ_2022.xlsx]原始数据'!$D:$D,MATCH($A12,'[AQ_2022.xlsx]原始数据'!$A:$A,0)),"")) | O12: =IF($A12="","",IFERROR(INDEX('[AQ_2023.xlsx]原始数据'!$D:$D,MATCH($A12,'[AQ_2023.xlsx]原始数据'!$A:$A,0)),"")) | P12: =IF($A12="","",IFERROR(INDEX('[AQ_2024.xlsx]原始数据'!$D:$D,MATCH($A12,'[AQ_2024.xlsx]原始数据'!$A:$A,0)),"")) | Q12: =IF($A12="","",IFERROR(INDEX('[AQ_2020.xlsx]原始数据'!$E:$E,MATCH($A12,'[AQ_2020.xlsx]原始数据'!$A:$A,0)),"")) | R12: =IF($A12="","",IFERROR(INDEX('[AQ_2021.xlsx]原始数据'!$E:$E,MATCH($A12,'[AQ_2021.xlsx]原始数据'!$A:$A,0)),"")) | S12: =IF($A12="","",IFERROR(INDEX('[AQ_2022.xlsx]原始数据'!$E:$E,MATCH($A12,'[AQ_2022.xlsx]原始数据'!$A:$A,0)),"")) | T12: =IF($A12="","",IFERROR(INDEX('[AQ_2023.xlsx]原始数据'!$E:$E,MATCH($A12,'[AQ_2023.xlsx]原始数据'!$A:$A,0)),"")) | U12: =IF($A12="","",IFERROR(INDEX('[AQ_2024.xlsx]原始数据'!$E:$E,MATCH($A12,'[AQ_2024.xlsx]原始数据'!$A:$A,0)),"")) | V12: =IF($A12="","",IFERROR(INDEX('[AQ_2020.xlsx]原始数据'!$F:$F,MATCH($A12,'[AQ_2020.xlsx]原始数据'!$A:$A,0)),"")) | W12: =IF($A12="","",IFERROR(INDEX('[AQ_2021.xlsx]原始数据'!$F:$F,MATCH($A12,'[AQ_2021.xlsx]原始数据'!$A:$A,0)),"")) | X12: =IF($A12="","",IFERROR(INDEX('[AQ_2022.xlsx]原始数据'!$F:$F,MATCH($A12,'[AQ_2022.xlsx]原始数据'!$A:$A,0)),"")) | Y12: =IF($A12="","",IFERROR(INDEX('[AQ_2023.xlsx]原始数据'!$F:$F,MATCH($A12,'[AQ_2023.xlsx]原始数据'!$A:$A,0)),"")) | Z12: =IF($A12="","",IFERROR(INDEX('[AQ_2024.xlsx]原始数据'!$F:$F,MATCH($A12,'[AQ_2024.xlsx]原始数据'!$A:$A,0)),"")) | AA12: =IFERROR(G12/B12,"") | AB12: =IFERROR(H12/C12,"") | AC12: =IFERROR(I12/D12,"") | AD12: =IFERROR(J12/E12,"") | AE12: =IFERROR(K12/F12,"") | AF12: =IFERROR(L12/B12,"") | AG12: =IFERROR(M12/C12,"") | AH12: =IFERROR(N12/D12,"") | AI12: =IFERROR(O12/E12,"") | AJ12: =IFERROR(P12/F12,"") | AK12: =IFERROR(Q12/B12,"") | AL12: =IFERROR(R12/C12,"") | AM12: =IFERROR(S12/D12,"") | AN12: =IFERROR(T12/E12,"") | AO12: =IFERROR(U12/F12,"")
B13: =IF($A13="","",IFERROR(INDEX('[AQ_2020.xlsx]原始数据'!$B:$B,MATCH($A13,'[AQ_2020.xlsx]原始数据'!$A:$A,0)),"")) | C13: =IF($A13="","",IFERROR(INDEX('[AQ_2021.xlsx]原始数据'!$B:$B,MATCH($A13,'[AQ_2021.xlsx]原始数据'!$A:$A,0)),"")) | D13: =IF($A13="","",IFERROR(INDEX('[AQ_2022.xlsx]原始数据'!$B:$B,MATCH($A13,'[AQ_2022.xlsx]原始数据'!$A:$A,0)),"")) | E13: =IF($A13="","",IFERROR(INDEX('[AQ_2023.xlsx]原始数据'!$B:$B,MATCH($A13,'[AQ_2023.xlsx]原始数据'!$A:$A,0)),"")) | F13: =IF($A13="","",IFERROR(INDEX('[AQ_2024.xlsx]原始数据'!$B:$B,MATCH($A13,'[AQ_2024.xlsx]原始数据'!$A:$A,0)),"")) | G13: =IF($A13="","",IFERROR(INDEX('[AQ_2020.xlsx]原始数据'!$C:$C,MATCH($A13,'[AQ_2020.xlsx]原始数据'!$A:$A,0)),"")) | H13: =IF($A13="","",IFERROR(INDEX('[AQ_2021.xlsx]原始数据'!$C:$C,MATCH($A13,'[AQ_2021.xlsx]原始数据'!$A:$A,0)),"")) | I13: =IF($A13="","",IFERROR(INDEX('[AQ_2022.xlsx]原始数据'!$C:$C,MATCH($A13,'[AQ_2022.xlsx]原始数据'!$A:$A,0)),"")) | J13: =IF($A13="","",IFERROR(INDEX('[AQ_2023.xlsx]原始数据'!$C:$C,MATCH($A13,'[AQ_2023.xlsx]原始数据'!$A:$A,0)),"")) | K13: =IF($A13="","",IFERROR(INDEX('[AQ_2024.xlsx]原始数据'!$C:$C,MATCH($A13,'[AQ_2024.xlsx]原始数据'!$A:$A,0)),"")) | L13: =IF($A13="","",IFERROR(INDEX('[AQ_2020.xlsx]原始数据'!$D:$D,MATCH($A13,'[AQ_2020.xlsx]原始数据'!$A:$A,0)),"")) | M13: =IF($A13="","",IFERROR(INDEX('[AQ_2021.xlsx]原始数据'!$D:$D,MATCH($A13,'[AQ_2021.xlsx]原始数据'!$A:$A,0)),"")) | N13: =IF($A13="","",IFERROR(INDEX('[AQ_2022.xlsx]原始数据'!$D:$D,MATCH($A13,'[AQ_2022.xlsx]原始数据'!$A:$A,0)),"")) | O13: =IF($A13="","",IFERROR(INDEX('[AQ_2023.xlsx]原始数据'!$D:$D,MATCH($A13,'[AQ_2023.xlsx]原始数据'!$A:$A,0)),"")) | P13: =IF($A13="","",IFERROR(INDEX('[AQ_2024.xlsx]原始数据'!$D:$D,MATCH($A13,'[AQ_2024.xlsx]原始数据'!$A:$A,0)),"")) | Q13: =IF($A13="","",IFERROR(INDEX('[AQ_2020.xlsx]原始数据'!$E:$E,MATCH($A13,'[AQ_2020.xlsx]原始数据'!$A:$A,0)),"")) | R13: =IF($A13="","",IFERROR(INDEX('[AQ_2021.xlsx]原始数据'!$E:$E,MATCH($A13,'[AQ_2021.xlsx]原始数据'!$A:$A,0)),"")) | S13: =IF($A13="","",IFERROR(INDEX('[AQ_2022.xlsx]原始数据'!$E:$E,MATCH($A13,'[AQ_2022.xlsx]原始数据'!$A:$A,0)),"")) | T13: =IF($A13="","",IFERROR(INDEX('[AQ_2023.xlsx]原始数据'!$E:$E,MATCH($A13,'[AQ_2023.xlsx]原始数据'!$A:$A,0)),"")) | U13: =IF($A13="","",IFERROR(INDEX('[AQ_2024.xlsx]原始数据'!$E:$E,MATCH($A13,'[AQ_2024.xlsx]原始数据'!$A:$A,0)),"")) | V13: =IF($A13="","",IFERROR(INDEX('[AQ_2020.xlsx]原始数据'!$F:$F,MATCH($A13,'[AQ_2020.xlsx]原始数据'!$A:$A,0)),"")) | W13: =IF($A13="","",IFERROR(INDEX('[AQ_2021.xlsx]原始数据'!$F:$F,MATCH($A13,'[AQ_2021.xlsx]原始数据'!$A:$A,0)),"")) | X13: =IF($A13="","",IFERROR(INDEX('[AQ_2022.xlsx]原始数据'!$F:$F,MATCH($A13,'[AQ_2022.xlsx]原始数据'!$A:$A,0)),"")) | Y13: =IF($A13="","",IFERROR(INDEX('[AQ_2023.xlsx]原始数据'!$F:$F,MATCH($A13,'[AQ_2023.xlsx]原始数据'!$A:$A,0)),"")) | Z13: =IF($A13="","",IFERROR(INDEX('[AQ_2024.xlsx]原始数据'!$F:$F,MATCH($A13,'[AQ_2024.xlsx]原始数据'!$A:$A,0)),"")) | AA13: =IFERROR(G13/B13,"") | AB13: =IFERROR(H13/C13,"") | AC13: =IFERROR(I13/D13,"") | AD13: =IFERROR(J13/E13,"") | AE13: =IFERROR(K13/F13,"") | AF13: =IFERROR(L13/B13,"") | AG13: =IFERROR(M13/C13,"") | AH13: =IFERROR(N13/D13,"") | AI13: =IFERROR(O13/E13,"") | AJ13: =IFERROR(P13/F13,"") | AK13: =IFERROR(Q13/B13,"") | AL13: =IFERROR(R13/C13,"") | AM13: =IFERROR(S13/D13,"") | AN13: =IFERROR(T13/E13,"") | AO13: =IFERROR(U13/F13,"")
B14: =IF($A14="","",IFERROR(INDEX('[AQ_2020.xlsx]原始数据'!$B:$B,MATCH($A14,'[AQ_2020.xlsx]原始数据'!$A:$A,0)),"")) | C14: =IF($A14="","",IFERROR(INDEX('[AQ_2021.xlsx]原始数据'!$B:$B,MATCH($A14,'[AQ_2021.xlsx]原始数据'!$A:$A,0)),"")) | D14: =IF($A14="","",IFERROR(INDEX('[AQ_2022.xlsx]原始数据'!$B:$B,MATCH($A14,'[AQ_2022.xlsx]原始数据'!$A:$A,0)),"")) | E14: =IF($A14="","",IFERROR(INDEX('[AQ_2023.xlsx]原始数据'!$B:$B,MATCH($A14,'[AQ_2023.xlsx]原始数据'!$A:$A,0)),"")) | F14: =IF($A14="","",IFERROR(INDEX('[AQ_2024.xlsx]原始数据'!$B:$B,MATCH($A14,'[AQ_2024.xlsx]原始数据'!$A:$A,0)),"")) | G14: =IF($A14="","",IFERROR(INDEX('[AQ_2020.xlsx]原始数据'!$C:$C,MATCH($A14,'[AQ_2020.xlsx]原始数据'!$A:$A,0)),"")) | H14: =IF($A14="","",IFERROR(INDEX('[AQ_2021.xlsx]原始数据'!$C:$C,MATCH($A14,'[AQ_2021.xlsx]原始数据'!$A:$A,0)),"")) | I14: =IF($A14="","",IFERROR(INDEX('[AQ_2022.xlsx]原始数据'!$C:$C,MATCH($A14,'[AQ_2022.xlsx]原始数据'!$A:$A,0)),"")) | J14: =IF($A14="","",IFERROR(INDEX('[AQ_2023.xlsx]原始数据'!$C:$C,MATCH($A14,'[AQ_2023.xlsx]原始数据'!$A:$A,0)),"")) | K14: =IF($A14="","",IFERROR(INDEX('[AQ_2024.xlsx]原始数据'!$C:$C,MATCH($A14,'[AQ_2024.xlsx]原始数据'!$A:$A,0)),"")) | L14: =IF($A14="","",IFERROR(INDEX('[AQ_2020.xlsx]原始数据'!$D:$D,MATCH($A14,'[AQ_2020.xlsx]原始数据'!$A:$A,0)),"")) | M14: =IF($A14="","",IFERROR(INDEX('[AQ_2021.xlsx]原始数据'!$D:$D,MATCH($A14,'[AQ_2021.xlsx]原始数据'!$A:$A,0)),"")) | N14: =IF($A14="","",IFERROR(INDEX('[AQ_2022.xlsx]原始数据'!$D:$D,MATCH($A14,'[AQ_2022.xlsx]原始数据'!$A:$A,0)),"")) | O14: =IF($A14="","",IFERROR(INDEX('[AQ_2023.xlsx]原始数据'!$D:$D,MATCH($A14,'[AQ_2023.xlsx]原始数据'!$A:$A,0)),"")) | P14: =IF($A14="","",IFERROR(INDEX('[AQ_2024.xlsx]原始数据'!$D:$D,MATCH($A14,'[AQ_2024.xlsx]原始数据'!$A:$A,0)),"")) | Q14: =IF($A14="","",IFERROR(INDEX('[AQ_2020.xlsx]原始数据'!$E:$E,MATCH($A14,'[AQ_2020.xlsx]原始数据'!$A:$A,0)),"")) | R14: =IF($A14="","",IFERROR(INDEX('[AQ_2021.xlsx]原始数据'!$E:$E,MATCH($A14,'[AQ_2021.xlsx]原始数据'!$A:$A,0)),"")) | S14: =IF($A14="","",IFERROR(INDEX('[AQ_2022.xlsx]原始数据'!$E:$E,MATCH($A14,'[AQ_2022.xlsx]原始数据'!$A:$A,0)),"")) | T14: =IF($A14="","",IFERROR(INDEX('[AQ_2023.xlsx]原始数据'!$E:$E,MATCH($A14,'[AQ_2023.xlsx]原始数据'!$A:$A,0)),"")) | U14: =IF($A14="","",IFERROR(INDEX('[AQ_2024.xlsx]原始数据'!$E:$E,MATCH($A14,'[AQ_2024.xlsx]原始数据'!$A:$A,0)),"")) | V14: =IF($A14="","",IFERROR(INDEX('[AQ_2020.xlsx]原始数据'!$F:$F,MATCH($A14,'[AQ_2020.xlsx]原始数据'!$A:$A,0)),"")) | W14: =IF($A14="","",IFERROR(INDEX('[AQ_2021.xlsx]原始数据'!$F:$F,MATCH($A14,'[AQ_2021.xlsx]原始数据'!$A:$A,0)),"")) | X14: =IF($A14="","",IFERROR(INDEX('[AQ_2022.xlsx]原始数据'!$F:$F,MATCH($A14,'[AQ_2022.xlsx]原始数据'!$A:$A,0)),"")) | Y14: =IF($A14="","",IFERROR(INDEX('[AQ_2023.xlsx]原始数据'!$F:$F,MATCH($A14,'[AQ_2023.xlsx]原始数据'!$A:$A,0)),"")) | Z14: =IF($A14="","",IFERROR(INDEX('[AQ_2024.xlsx]原始数据'!$F:$F,MATCH($A14,'[AQ_2024.xlsx]原始数据'!$A:$A,0)),"")) | AA14: =IFERROR(G14/B14,"") | AB14: =IFERROR(H14/C14,"") | AC14: =IFERROR(I14/D14,"") | AD14: =IFERROR(J14/E14,"") | AE14: =IFERROR(K14/F14,"") | AF14: =IFERROR(L14/B14,"") | AG14: =IFERROR(M14/C14,"") | AH14: =IFERROR(N14/D14,"") | AI14: =IFERROR(O14/E14,"") | AJ14: =IFERROR(P14/F14,"") | AK14: =IFERROR(Q14/B14,"") | AL14: =IFERROR(R14/C14,"") | AM14: =IFERROR(S14/D14,"") | AN14: =IFERROR(T14/E14,"") | AO14: =IFERROR(U14/F14,"")
... B1002: =IF($A1002="","",IFERROR(INDEX('[AQ_2020.xlsx]原始数据'!$B:$B,MATCH($A1002,'[AQ_2020.xlsx]原始数据'!$A:$A,0)),"")) | C1002: =IF($A1002="","",IFERROR(INDEX('[AQ_2021.xlsx]原始数据'!$B:$B,MATCH($A1002,'[AQ_2021.xlsx]原始数据'!$A:$A,0)),"")) | D1002: =IF($A1002="","",IFERROR(INDEX('[AQ_2022.xlsx]原始数据'!$B:$B,MATCH($A1002,'[AQ_2022.xlsx]原始数据'!$A:$A,0)),"")) | E1002: =IF($A1002="","",IFERROR(INDEX('[AQ_2023.xlsx]原始数据'!$B:$B,MATCH($A1002,'[AQ_2023.xlsx]原始数据'!$A:$A,0)),"")) | F1002: =IF($A1002="","",IFERROR(INDEX('[AQ_2024.xlsx]原始数据'!$B:$B,MATCH($A1002,'[AQ_2024.xlsx]原始数据'!$A:$A,0)),"")) | G1002: =IF($A1002="","",IFERROR(INDEX('[AQ_2020.xlsx]原始数据'!$C:$C,MATCH($A1002,'[AQ_2020.xlsx]原始数据'!$A:$A,0)),"")) | H1002: =IF($A1002="","",IFERROR(INDEX('[AQ_2021.xlsx]原始数据'!$C:$C,MATCH($A1002,'[AQ_2021.xlsx]原始数据'!$A:$A,0)),"")) | I1002: =IF($A1002="","",IFERROR(INDEX('[AQ_2022.xlsx]原始数据'!$C:$C,MATCH($A1002,'[AQ_2022.xlsx]原始数据'!$A:$A,0)),"")) | J1002: =IF($A1002="","",IFERROR(INDEX('[AQ_2023.xlsx]原始数据'!$C:$C,MATCH($A1002,'[AQ_2023.xlsx]原始数据'!$A:$A,0)),"")) | K1002: =IF($A1002="","",IFERROR(INDEX('[AQ_2024.xlsx]原始数据'!$C:$C,MATCH($A1002,'[AQ_2024.xlsx]原始数据'!$A:$A,0)),"")) | L1002: =IF($A1002="","",IFERROR(INDEX('[AQ_2020.xlsx]原始数据'!$D:$D,MATCH($A1002,'[AQ_2020.xlsx]原始数据'!$A:$A,0)),"")) | M1002: =IF($A1002="","",IFERROR(INDEX('[AQ_2021.xlsx]原始数据'!$D:$D,MATCH($A1002,'[AQ_2021.xlsx]原始数据'!$A:$A,0)),"")) | N1002: =IF($A1002="","",IFERROR(INDEX('[AQ_2022.xlsx]原始数据'!$D:$D,MATCH($A1002,'[AQ_2022.xlsx]原始数据'!$A:$A,0)),"")) | O1002: =IF($A1002="","",IFERROR(INDEX('[AQ_2023.xlsx]原始数据'!$D:$D,MATCH($A1002,'[AQ_2023.xlsx]原始数据'!$A:$A,0)),"")) | P1002: =IF($A1002="","",IFERROR(INDEX('[AQ_2024.xlsx]原始数据'!$D:$D,MATCH($A1002,'[AQ_2024.xlsx]原始数据'!$A:$A,0)),"")) | Q1002: =IF($A1002="","",IFERROR(INDEX('[AQ_2020.xlsx]原始数据'!$E:$E,MATCH($A1002,'[AQ_2020.xlsx]原始数据'!$A:$A,0)),"")) | R1002: =IF($A1002="","",IFERROR(INDEX('[AQ_2021.xlsx]原始数据'!$E:$E,MATCH($A1002,'[AQ_2021.xlsx]原始数据'!$A:$A,0)),"")) | S1002: =IF($A1002="","",IFERROR(INDEX('[AQ_2022.xlsx]原始数据'!$E:$E,MATCH($A1002,'[AQ_2022.xlsx]原始数据'!$A:$A,0)),"")) | T1002: =IF($A1002="","",IFERROR(INDEX('[AQ_2023.xlsx]原始数据'!$E:$E,MATCH($A1002,'[AQ_2023.xlsx]原始数据'!$A:$A,0)),"")) | U1002: =IF($A1002="","",IFERROR(INDEX('[AQ_2024.xlsx]原始数据'!$E:$E,MATCH($A1002,'[AQ_2024.xlsx]原始数据'!$A:$A,0)),"")) | V1002: =IF($A1002="","",IFERROR(INDEX('[AQ_2020.xlsx]原始数据'!$F:$F,MATCH($A1002,'[AQ_2020.xlsx]原始数据'!$A:$A,0)),"")) | W1002: =IF($A1002="","",IFERROR(INDEX('[AQ_2021.xlsx]原始数据'!$F:$F,MATCH($A1002,'[AQ_2021.xlsx]原始数据'!$A:$A,0)),"")) | X1002: =IF($A1002="","",IFERROR(INDEX('[AQ_2022.xlsx]原始数据'!$F:$F,MATCH($A1002,'[AQ_2022.xlsx]原始数据'!$A:$A,0)),"")) | Y1002: =IF($A1002="","",IFERROR(INDEX('[AQ_2023.xlsx]原始数据'!$F:$F,MATCH($A1002,'[AQ_2023.xlsx]原始数据'!$A:$A,0)),"")) | Z1002: =IF($A1002="","",IFERROR(INDEX('[AQ_2024.xlsx]原始数据'!$F:$F,MATCH($A1002,'[AQ_2024.xlsx]原始数据'!$A:$A,0)),"")) | AA1002: =IFERROR(G1002/B1002,"") | AB1002: =IFERROR(H1002/C1002,"") | AC1002: =IFERROR(I1002/D1002,"") | AD1002: =IFERROR(J1002/E1002,"") | AE1002: =IFERROR(K1002/F1002,"") | AF1002: =IFERROR(L1002/B1002,"") | AG1002: =IFERROR(M1002/C1002,"") | AH1002: =IFERROR(N1002/D1002,"") | AI1002: =IFERROR(O1002/E1002,"") | AJ1002: =IFERROR(P1002/F1002,"") | AK1002: =IFERROR(Q1002/B1002,"") | AL1002: =IFERROR(R1002/C1002,"") | AM1002: =IFERROR(S1002/D1002,"") | AN1002: =IFERROR(T1002/E1002,"") | AO1002: =IFERROR(U1002/F1002,"")

Sheet 趋势_兼容版
A1: 指标/年份 | B1: 2020 | C1: 2021 | D1: 2022 | E1: 2023 | F1: 2024
A2: 贷款总额-合计 | B2: =SUM('汇总_兼容版'!$B$3:$B$1002) | C2: =SUM('汇总_兼容版'!$C$3:$C$1002) | D2: =SUM('汇总_兼容版'!$D$3:$D$1002) | E2: =SUM('汇总_兼容版'!$E$3:$E$1002) | F2: =SUM('汇总_兼容版'!$F$3:$F$1002)
A3: 逾期-合计 | B3: =SUM('汇总_兼容版'!$G$3:$G$1002) | C3: =SUM('汇总_兼容版'!$H$3:$H$1002) | D3: =SUM('汇总_兼容版'!$I$3:$I$1002) | E3: =SUM('汇总_兼容版'!$J$3:$J$1002) | F3: =SUM('汇总_兼容版'!$K$3:$K$1002)
A4: 不良-合计 | B4: =SUM('汇总_兼容版'!$L$3:$L$1002) | C4: =SUM('汇总_兼容版'!$M$3:$M$1002) | D4: =SUM('汇总_兼容版'!$N$3:$N$1002) | E4: =SUM('汇总_兼容版'!$O$3:$O$1002) | F4: =SUM('汇总_兼容版'!$P$3:$P$1002)
A5: 关注-合计 | B5: =SUM('汇总_兼容版'!$Q$3:$Q$1002) | C5: =SUM('汇总_兼容版'!$R$3:$R$1002) | D5: =SUM('汇总_兼容版'!$S$3:$S$1002) | E5: =SUM('汇总_兼容版'!$T$3:$T$1002) | F5: =SUM('汇总_兼容版'!$U$3:$U$1002)
A6: 新发生不良-合计 | B6: =SUM('汇总_兼容版'!$V$3:$V$1002) | C6: =SUM('汇总_兼容版'!$W$3:$W$1002) | D6: =SUM('汇总_兼容版'!$X$3:$X$1002) | E6: =SUM('汇总_兼容版'!$Y$3:$Y$1002) | F6: =SUM('汇总_兼容版'!$Z$3:$Z$1002)
A7: 逾期率-合计 | B7: =IFERROR(SUM('汇总_兼容版'!$G$3:$G$1002)/SUM('汇总_兼容版'!$B$3:$B$1002),"") | C7: =IFERROR(SUM('汇总_兼容版'!$H$3:$H$1002)/SUM('汇总_兼容版'!$C$3:$C$1002),"") | D7: =IFERROR(SUM('汇总_兼容版'!$I$3:$I$1002)/SUM('汇总_兼容版'!$D$3:$D$1002),"") | E7: =IFERROR(SUM('汇总_兼容版'!$J$3:$J$1002)/SUM('汇总_兼容版'!$E$3:$E$1002),"") | F7: =IFERROR(SUM('汇总_兼容版'!$K$3:$K$1002)/SUM('汇总_兼容版'!$F$3:$F$1002),"")
A8: 不良率-合计 | B8: =IFERROR(SUM('汇总_兼容版'!$L$3:$L$1002)/SUM('汇总_兼容版'!$B$3:$B$1002),"") | C8: =IFERROR(SUM('汇总_兼容版'!$M$3:$M$1002)/SUM('汇总_兼容版'!$C$3:$C$1002),"") | D8: =IFERROR(SUM('汇总_兼容版'!$N$3:$N$1002)/SUM('汇总_兼容版'!$D$3:$D$1002),"") | E8: =IFERROR(SUM('汇总_兼容版'!$O$3:$O$1002)/SUM('汇总_兼容版'!$E$3:$E$1002),"") | F8: =IFERROR(SUM('汇总_兼容版'!$P$3:$P$1002)/SUM('汇总_兼容版'!$F$3:$F$1002),"")
A9: 关注率-合计 | B9: =IFERROR(SUM('汇总_兼容版'!$Q$3:$Q$1002)/SUM('汇总_兼容版'!$B$3:$B$1002),"") | C9: =IFERROR(SUM('汇总_兼容版'!$R$3:$R$1002)/SUM('汇总_兼容版'!$C$3:$C$1002),"") | D9: =IFERROR(SUM('汇总_兼容版'!$S$3:$S$1002)/SUM('汇总_兼容版'!$D$3:$D$1002),"") | E9: =IFERROR(SUM('汇总_兼容版'!$T$3:$T$1002)/SUM('汇总_兼容版'!$E$3:$E$1002),"") | F9: =IFERROR(SUM('汇总_兼容版'!$U$3:$U$1002)/SUM('汇总_兼容版'!$F$3:$F$1002),"")

Sheet 辅助
A1: 2020年_银行 | B1: 2021年_银行 | C1: 2022年_银行 | D1: 2023年_银行 | E1: 2024年_银行 | G1: 合并银行
A2: =IFERROR(INDEX('[AQ_2020.xlsx]原始数据'!$A:$A,ROW(A1)+1),"") | B2: =IFERROR(INDEX('[AQ_2021.xlsx]原始数据'!$A:$A,ROW(A1)+1),"") | C2: =IFERROR(INDEX('[AQ_2022.xlsx]原始数据'!$A:$A,ROW(A1)+1),"") | D2: =IFERROR(INDEX('[AQ_2023.xlsx]原始数据'!$A:$A,ROW(A1)+1),"") | E2: =IFERROR(INDEX('[AQ_2024.xlsx]原始数据'!$A:$A,ROW(A1)+1),"") | G2: =IF(1<=1000,INDEX($A$2:$A$1001,1),IF(1<=2000,INDEX($B$2:$B$1001,-999),IF(1<=3000,INDEX($C$2:$C$1001,-1999),IF(1<=4000,INDEX($D$2:$D$1001,-2999),IF(1<=5000,INDEX($E$2:$E$1001,-3999),"")))))
A3: =IFERROR(INDEX('[AQ_2020.xlsx]原始数据'!$A:$A,ROW(A1)+2),"") | B3: =IFERROR(INDEX('[AQ_2021.xlsx]原始数据'!$A:$A,ROW(A1)+2),"") | C3: =IFERROR(INDEX('[AQ_2022.xlsx]原始数据'!$A:$A,ROW(A1)+2),"") | D3: =IFERROR(INDEX('[AQ_2023.xlsx]原始数据'!$A:$A,ROW(A1)+2),"") | E3: =IFERROR(INDEX('[AQ_2024.xlsx]原始数据'!$A:$A,ROW(A1)+2),"") | G3: =IF(2<=1000,INDEX($A$2:$A$1001,2),IF(2<=2000,INDEX($B$2:$B$1001,-998),IF(2<=3000,INDEX($C$2:$C$1001,-1998),IF(2<=4000,INDEX($D$2:$D$1001,-2998),IF(2<=5000,INDEX($E$2:$E$1001,-3998),"")))))
A4: =IFERROR(INDEX('[AQ_2020.xlsx]原始数据'!$A:$A,ROW(A1)+3),"") | B4: =IFERROR(INDEX('[AQ_2021.xlsx]原始数据'!$A:$A,ROW(A1)+3),"") | C4: =IFERROR(INDEX('[AQ_2022.xlsx]原始数据'!$A:$A,ROW(A1)+3),"") | D4: =IFERROR(INDEX('[AQ_2023.xlsx]原始数据'!$A:$A,ROW(A1)+3),"") | E4: =IFERROR(INDEX('[AQ_2024.xlsx]原始数据'!$A:$A,ROW(A1)+3),"") | G4: =IF(3<=1000,INDEX($A$2:$A$1001,3),IF(3<=2000,INDEX($B$2:$B$1001,-997),IF(3<=3000,INDEX($C$2:$C$1001,-1997),IF(3<=4000,INDEX($D$2:$D$1001,-2997),IF(3<=5000,INDEX($E$2:$E$1001,-3997),"")))))
A5: =IFERROR(INDEX('[AQ_2020.xlsx]原始数据'!$A:$A,ROW(A1)+4),"") | B5: =IFERROR(INDEX('[AQ_2021.xlsx]原始数据'!$A:$A,ROW(A1)+4),"") | C5: =IFERROR(INDEX('[AQ_2022.xlsx]原始数据'!$A:$A,ROW(A1)+4),"") | D5: =IFERROR(INDEX('[AQ_2023.xlsx]原始数据'!$A:$A,ROW(A1)+4),"") | E5: =IFERROR(INDEX('[AQ_2024.xlsx]原始数据'!$A:$A,ROW(A1)+4),"") | G5: =IF(4<=1000,INDEX($A$2:$A$1001,4),IF(4<=2000,INDEX($B$2:$B$1001,-996),IF(4<=3000,INDEX($C$2:$C$1001,-1996),IF(4<=4000,INDEX($D$2:$D$1001,-2996),IF(4<=5000,INDEX($E$2:$E$1001,-3996),"")))))
A6: =IFERROR(INDEX('[AQ_2020.xlsx]原始数据'!$A:$A,ROW(A1)+5),"") | B6: =IFERROR(INDEX('[AQ_2021.xlsx]原始数据'!$A:$A,ROW(A1)+5),"") | C6: =IFERROR(INDEX('[AQ_2022.xlsx]原始数据'!$A:$A,ROW(A1)+5),"") | D6: =IFERROR(INDEX('[AQ_2023.xlsx]原始数据'!$A:$A,ROW(A1)+5),"") | E6: =IFERROR(INDEX('[AQ_2024.xlsx]原始数据'!$A:$A,ROW(A1)+5),"") | G6: =IF(5<=1000,INDEX($A$2:$A$1001,5),IF(5<=2000,INDEX($B$2:$B$1001,-995),IF(5<=3000,INDEX($C$2:$C$1001,-1995),IF(5<=4000,INDEX($D$2:$D$1001,-2995),IF(5<=5000,INDEX($E$2:$E$1001,-3995),"")))))
A7: =IFERROR(INDEX('[AQ_2020.xlsx]原始数据'!$A:$A,ROW(A1)+6),"") | B7: =IFERROR(INDEX('[AQ_2021.xlsx]原始数据'!$A:$A,ROW(A1)+6),"") | C7: =IFERROR(INDEX('[AQ_2022.xlsx]原始数据'!$A:$A,ROW(A1)+6),"") | D7: =IFERROR(INDEX('[AQ_2023.xlsx]原始数据'!$A:$A,ROW(A1)+6),"") | E7: =IFERROR(INDEX('[AQ_2024.xlsx]原始数据'!$A:$A,ROW(A1)+6),"") | G7: =IF(6<=1000,INDEX($A$2:$A$1001,6),IF(6<=2000,INDEX($B$2:$B$1001,-994),IF(6<=3000,INDEX($C$2:$C$1001,-1994),IF(6<=4000,INDEX($D$2:$D$1001,-2994),IF(6<=5000,INDEX($E$2:$E$1001,-3994),"")))))
A8: =IFERROR(INDEX('[AQ_2020.xlsx]原始数据'!$A:$A,ROW(A1)+7),"") | B8: =IFERROR(INDEX('[AQ_2021.xlsx]原始数据'!$A:$A,ROW(A1)+7),"") | C8: =IFERROR(INDEX('[AQ_2022.xlsx]原始数据'!$A:$A,ROW(A1)+7),"") | D8: =IFERROR(INDEX('[AQ_2023.xlsx]原始数据'!$A:$A,ROW(A1)+7),"") | E8: =IFERROR(INDEX('[AQ_2024.xlsx]原始数据'!$A:$A,ROW(A1)+7),"") | G8: =IF(7<=1000,INDEX($A$2:$A$1001,7),IF(7<=2000,INDEX($B$2:$B$1001,-993),IF(7<=3000,INDEX($C$2:$C$1001,-1993),IF(7<=4000,INDEX($D$2:$D$1001,-2993),IF(7<=5000,INDEX($E$2:$E$1001,-3993),"")))))
A9: =IFERROR(INDEX('[AQ_2020.xlsx]原始数据'!$A:$A,ROW(A1)+8),"") | B9: =IFERROR(INDEX('[AQ_2021.xlsx]原始数据'!$A:$A,ROW(A1)+8),"") | C9: =IFERROR(INDEX('[AQ_2022.xlsx]原始数据'!$A:$A,ROW(A1)+8),"") | D9: =IFERROR(INDEX('[AQ_2023.xlsx]原始数据'!$A:$A,ROW(A1)+8),"") | E9: =IFERROR(INDEX('[AQ_2024.xlsx]原始数据'!$A:$A,ROW(A1)+8),"") | G9: =IF(8<=1000,INDEX($A$2:$A$1001,8),IF(8<=2000,INDEX($B$2:$B$1001,-992),IF(8<=3000,INDEX($C$2:$C$1001,-1992),IF(8<=4000,INDEX($D$2:$D$1001,-2992),IF(8<=5000,INDEX($E$2:$E$1001,-3992),"")))))
A10: =IFERROR(INDEX('[AQ_2020.xlsx]原始数据'!$A:$A,ROW(A1)+9),"") | B10: =IFERROR(INDEX('[AQ_2021.xlsx]原始数据'!$A:$A,ROW(A1)+9),"") | C10: =IFERROR(INDEX('[AQ_2022.xlsx]原始数据'!$A:$A,ROW(A1)+9),"") | D10: =IFERROR(INDEX('[AQ_2023.xlsx]原始数据'!$A:$A,ROW(A1)+9),"") | E10: =IFERROR(INDEX('[AQ_2024.xlsx]原始数据'!$A:$A,ROW(A1)+9),"") | G10: =IF(9<=1000,INDEX($A$2:$A$1001,9),IF(9<=2000,INDEX($B$2:$B$1001,-991),IF(9<=3000,INDEX($C$2:$C$1001,-1991),IF(9<=4000,INDEX($D$2:$D$1001,-2991),IF(9<=5000,INDEX($E$2:$E$1001,-3991),"")))))
A11: =IFERROR(INDEX('[AQ_2020.xlsx]原始数据'!$A:$A,ROW(A1)+10),"") | B11: =IFERROR(INDEX('[AQ_2021.xlsx]原始数据'!$A:$A,ROW(A1)+10),"") | C11: =IFERROR(INDEX('[AQ_2022.xlsx]原始数据'!$A:$A,ROW(A1)+10),"") | D11: =IFERROR(INDEX('[AQ_2023.xlsx]原始数据'!$A:$A,ROW(A1)+10),"") | E11: =IFERROR(INDEX('[AQ_2024.xlsx]原始数据'!$A:$A,ROW(A1)+10),"") | G11: =IF(10<=1000,INDEX($A$2:$A$1001,10),IF(10<=2000,INDEX($B$2:$B$1001,-990),IF(10<=3000,INDEX($C$2:$C$1001,-1990),IF(10<=4000,INDEX($D$2:$D$1001,-2990),IF(10<=5000,INDEX($E$2:$E$1001,-3990),"")))))
A12: =IFERROR(INDEX('[AQ_2020.xlsx]原始数据'!$A:$A,ROW(A1)+11),"") | B12: =IFERROR(INDEX('[AQ_2021.xlsx]原始数据'!$A:$A,ROW(A1)+11),"") | C12: =IFERROR(INDEX('[AQ_2022.xlsx]原始数据'!$A:$A,ROW(A1)+11),"") | D12: =IFERROR(INDEX('[AQ_2023.xlsx]原始数据'!$A:$A,ROW(A1)+11),"") | E12: =IFERROR(INDEX('[AQ_2024.xlsx]原始数据'!$A:$A,ROW(A1)+11),"") | G12: =IF(11<=1000,INDEX($A$2:$A$1001,11),IF(11<=2000,INDEX($B$2:$B$1001,-989),IF(11<=3000,INDEX($C$2:$C$1001,-1989),IF(11<=4000,INDEX($D$2:$D$1001,-2989),IF(11<=5000,INDEX($E$2:$E$1001,-3989),"")))))
A13: =IFERROR(INDEX('[AQ_2020.xlsx]原始数据'!$A:$A,ROW(A1)+12),"") | B13: =IFERROR(INDEX('[AQ_2021.xlsx]原始数据'!$A:$A,ROW(A1)+12),"") | C13: =IFERROR(INDEX('[AQ_2022.xlsx]原始数据'!$A:$A,ROW(A1)+12),"") | D13: =IFERROR(INDEX('[AQ_2023.xlsx]原始数据'!$A:$A,ROW(A1)+12),"") | E13: =IFERROR(INDEX('[AQ_2024.xlsx]原始数据'!$A:$A,ROW(A1)+12),"") | G13: =IF(12<=1000,INDEX($A$2:$A$1001,12),IF(12<=2000,INDEX($B$2:$B$1001,-988),IF(12<=3000,INDEX($C$2:$C$1001,-1988),IF(12<=4000,INDEX($D$2:$D$1001,-2988),IF(12<=5000,INDEX($E$2:$E$1001,-3988),"")))))
A14: =IFERROR(INDEX('[AQ_2020.xlsx]原始数据'!$A:$A,ROW(A1)+13),"") | B14: =IFERROR(INDEX('[AQ_2021.xlsx]原始数据'!$A:$A,ROW(A1)+13),"") | C14: =IFERROR(INDEX('[AQ_2022.xlsx]原始数据'!$A:$A,ROW(A1)+13),"") | D14: =IFERROR(INDEX('[AQ_2023.xlsx]原始数据'!$A:$A,ROW(A1)+13),"") | E14: =IFERROR(INDEX('[AQ_2024.xlsx]原始数据'!$A:$A,ROW(A1)+13),"") | G14: =IF(13<=1000,INDEX($A$2:$A$1001,13),IF(13<=2000,INDEX($B$2:$B$1001,-987),IF(13<=3000,INDEX($C$2:$C$1001,-1987),IF(13<=4000,INDEX($D$2:$D$1001,-2987),IF(13<=5000,INDEX($E$2:$E$1001,-3987),"")))))
A15: =IFERROR(INDEX('[AQ_2020.xlsx]原始数据'!$A:$A,ROW(A1)+14),"") | B15: =IFERROR(INDEX('[AQ_2021.xlsx]原始数据'!$A:$A,ROW(A1)+14),"") | C15: =IFERROR(INDEX('[AQ_2022.xlsx]原始数据'!$A:$A,ROW(A1)+14),"") | D15: =IFERROR(INDEX('[AQ_2023.xlsx]原始数据'!$A:$A,ROW(A1)+14),"") | E15: =IFERROR(INDEX('[AQ_2024.xlsx]原始数据'!$A:$A,ROW(A1)+14),"") | G15: =IF(14<=1000,INDEX($A$2:$A$1001,14),IF(14<=2000,INDEX($B$2:$B$1001,-986),IF(14<=3000,INDEX($C$2:$C$1001,-1986),IF(14<=4000,INDEX($D$2:$D$1001,-2986),IF(14<=5000,INDEX($E$2:$E$1001,-3986),"")))))
A16: =IFERROR(INDEX('[AQ_2020.xlsx]原始数据'!$A:$A,ROW(A1)+15),"") | B16: =IFERROR(INDEX('[AQ_2021.xlsx]原始数据'!$A:$A,ROW(A1)+15),"") | C16: =IFERROR(INDEX('[AQ_2022.xlsx]原始数据'!$A:$A,ROW(A1)+15),"") | D16: =IFERROR(INDEX('[AQ_2023.xlsx]原始数据'!$A:$A,ROW(A1)+15),"") | E16: =IFERROR(INDEX('[AQ_2024.xlsx]原始数据'!$A:$A,ROW(A1)+15),"") | G16: =IF(15<=1000,INDEX($A$2:$A$1001,15),IF(15<=2000,INDEX($B$2:$B$1001,-985),IF(15<=3000,INDEX($C$2:$C$1001,-1985),IF(15<=4000,INDEX($D$2:$D$1001,-2985),IF(15<=5000,INDEX($E$2:$E$1001,-3985),"")))))
A17: =IFERROR(INDEX('[AQ_2020.xlsx]原始数据'!$A:$A,ROW(A1)+16),"") | B17: =IFERROR(INDEX('[AQ_2021.xlsx]原始数据'!$A:$A,ROW(A1)+16),"") | C17: =IFERROR(INDEX('[AQ_2022.xlsx]原始数据'!$A:$A,ROW(A1)+16),"") | D17: =IFERROR(INDEX('[AQ_2023.xlsx]原始数据'!$A:$A,ROW(A1)+16),"") | E17: =IFERROR(INDEX('[AQ_2024.xlsx]原始数据'!$A:$A,ROW(A1)+16),"") | G17: =IF(16<=1000,INDEX($A$2:$A$1001,16),IF(16<=2000,INDEX($B$2:$B$1001,-984),IF(16<=3000,INDEX($C$2:$C$1001,-1984),IF(16<=4000,INDEX($D$2:$D$1001,-2984),IF(16<=5000,INDEX($E$2:$E$1001,-3984),"")))))
A18: =IFERROR(INDEX('[AQ_2020.xlsx]原始数据'!$A:$A,ROW(A1)+17),"") | B18: =IFERROR(INDEX('[AQ_2021.xlsx]原始数据'!$A:$A,ROW(A1)+17),"") | C18: =IFERROR(INDEX('[AQ_2022.xlsx]原始数据'!$A:$A,ROW(A1)+17),"") | D18: =IFERROR(INDEX('[AQ_2023.xlsx]原始数据'!$A:$A,ROW(A1)+17),"") | E18: =IFERROR(INDEX('[AQ_2024.xlsx]原始数据'!$A:$A,ROW(A1)+17),"") | G18: =IF(17<=1000,INDEX($A$2:$A$1001,17),IF(17<=2000,INDEX($B$2:$B$1001,-983),IF(17<=3000,INDEX($C$2:$C$1001,-1983),IF(17<=4000,INDEX($D$2:$D$1001,-2983),IF(17<=5000,INDEX($E$2:$E$1001,-3983),"")))))
A19: =IFERROR(INDEX('[AQ_2020.xlsx]原始数据'!$A:$A,ROW(A1)+18),"") | B19: =IFERROR(INDEX('[AQ_2021.xlsx]原始数据'!$A:$A,ROW(A1)+18),"") | C19: =IFERROR(INDEX('[AQ_2022.xlsx]原始数据'!$A:$A,ROW(A1)+18),"") | D19: =IFERROR(INDEX('[AQ_2023.xlsx]原始数据'!$A:$A,ROW(A1)+18),"") | E19: =IFERROR(INDEX('[AQ_2024.xlsx]原始数据'!$A:$A,ROW(A1)+18),"") | G19: =IF(18<=1000,INDEX($A$2:$A$1001,18),IF(18<=2000,INDEX($B$2:$B$1001,-982),IF(18<=3000,INDEX($C$2:$C$1001,-1982),IF(18<=4000,INDEX($D$2:$D$1001,-2982),IF(18<=5000,INDEX($E$2:$E$1001,-3982),"")))))
A20: =IFERROR(INDEX('[AQ_2020.xlsx]原始数据'!$A:$A,ROW(A1)+19),"") | B20: =IFERROR(INDEX('[AQ_2021.xlsx]原始数据'!$A:$A,ROW(A1)+19),"") | C20: =IFERROR(INDEX('[AQ_2022.xlsx]原始数据'!$A:$A,ROW(A1)+19),"") | D20: =IFERROR(INDEX('[AQ_2023.xlsx]原始数据'!$A:$A,ROW(A1)+19),"") | E20: =IFERROR(INDEX('[AQ_2024.xlsx]原始数据'!$A:$A,ROW(A1)+19),"") | G20: =IF(19<=1000,INDEX($A$2:$A$1001,19),IF(19<=2000,INDEX($B$2:$B$1001,-981),IF(19<=3000,INDEX($C$2:$C$1001,-1981),IF(19<=4000,INDEX($D$2:$D$1001,-2981),IF(19<=5000,INDEX($E$2:$E$1001,-3981),"")))))
A21: =IFERROR(INDEX('[AQ_2020.xlsx]原始数据'!$A:$A,ROW(A1)+20),"") | B21: =IFERROR(INDEX('[AQ_2021.xlsx]原始数据'!$A:$A,ROW(A1)+20),"") | C21: =IFERROR(INDEX('[AQ_2022.xlsx]原始数据'!$A:$A,ROW(A1)+20),"") | D21: =IFERROR(INDEX('[AQ_2023.xlsx]原始数据'!$A:$A,ROW(A1)+20),"") | E21: =IFERROR(INDEX('[AQ_2024.xlsx]原始数据'!$A:$A,ROW(A1)+20),"") | G21: =IF(20<=1000,INDEX($A$2:$A$1001,20),IF(20<=2000,INDEX($B$2:$B$1001,-980),IF(20<=3000,INDEX($C$2:$C$1001,-1980),IF(20<=4000,INDEX($D$2:$D$1001,-2980),IF(20<=5000,INDEX($E$2:$E$1001,-3980),"")))))
A22: =IFERROR(INDEX('[AQ_2020.xlsx]原始数据'!$A:$A,ROW(A1)+21),"") | B22: =IFERROR(INDEX('[AQ_2021.xlsx]原始数据'!$A:$A,ROW(A1)+21),"") | C22: =IFERROR(INDEX('[AQ_2022.xlsx]原始数据'!$A:$A,ROW(A1)+21),"") | D22: =IFERROR(INDEX('[AQ_2023.xlsx]原始数据'!$A:$A,ROW(A1)+21),"") | E22: =IFERROR(INDEX('[AQ_2024.xlsx]原始数据'!$A:$A,ROW(A1)+21),"") | G22: =IF(21<=1000,INDEX($A$2:$A$1001,21),IF(21<=2000,INDEX($B$2:$B$1001,-979),IF(21<=3000,INDEX($C$2:$C$1001,-1979),IF(21<=4000,INDEX($D$2:$D$1001,-2979),IF(21<=5000,INDEX($E$2:$E$1001,-3979),"")))))
A23: =IFERROR(INDEX('[AQ_2020.xlsx]原始数据'!$A:$A,ROW(A1)+22),"") | B23: =IFERROR(INDEX('[AQ_2021.xlsx]原始数据'!$A:$A,ROW(A1)+22),"") | C23: =IFERROR(INDEX('[AQ_2022.xlsx]原始数据'!$A:$A,ROW(A1)+22),"") | D23: =IFERROR(INDEX('[AQ_2023.xlsx]原始数据'!$A:$A,ROW(A1)+22),"") | E23: =IFERROR(INDEX('[AQ_2024.xlsx]原始数据'!$A:$A,ROW(A1)+22),"") | G23: =IF(22<=1000,INDEX($A$2:$A$1001,22),IF(22<=2000,INDEX($B$2:$B$1001,-978),IF(22<=3000,INDEX($C$2:$C$1001,-1978),IF(22<=4000,INDEX($D$2:$D$1001,-2978),IF(22<=5000,INDEX($E$2:$E$1001,-3978),"")))))
A24: =IFERROR(INDEX('[AQ_2020.xlsx]原始数据'!$A:$A,ROW(A1)+23),"") | B24: =IFERROR(INDEX('[AQ_2021.xlsx]原始数据'!$A:$A,ROW(A1)+23),"") | C24: =IFERROR(INDEX('[AQ_2022.xlsx]原始数据'!$A:$A,ROW(A1)+23),"") | D24: =IFERROR(INDEX('[AQ_2023.xlsx]原始数据'!$A:$A,ROW(A1)+23),"") | E24: =IFERROR(INDEX('[AQ_2024.xlsx]原始数据'!$A:$A,ROW(A1)+23),"") | G24: =IF(23<=1000,INDEX($A$2:$A$1001,23),IF(23<=2000,INDEX($B$2:$B$1001,-977),IF(23<=3000,INDEX($C$2:$C$1001,-1977),IF(23<=4000,INDEX($D$2:$D$1001,-2977),IF(23<=5000,INDEX($E$2:$E$1001,-3977),"")))))
A25: =IFERROR(INDEX('[AQ_2020.xlsx]原始数据'!$A:$A,ROW(A1)+24),"") | B25: =IFERROR(INDEX('[AQ_2021.xlsx]原始数据'!$A:$A,ROW(A1)+24),"") | C25: =IFERROR(INDEX('[AQ_2022.xlsx]原始数据'!$A:$A,ROW(A1)+24),"") | D25: =IFERROR(INDEX('[AQ_2023.xlsx]原始数据'!$A:$A,ROW(A1)+24),"") | E25: =IFERROR(INDEX('[AQ_2024.xlsx]原始数据'!$A:$A,ROW(A1)+24),"") | G25: =IF(24<=1000,INDEX($A$2:$A$1001,24),IF(24<=2000,INDEX($B$2:$B$1001,-976),IF(24<=3000,INDEX($C$2:$C$1001,-1976),IF(24<=4000,INDEX($D$2:$D$1001,-2976),IF(24<=5000,INDEX($E$2:$E$1001,-3976),"")))))
A26: =IFERROR(INDEX('[AQ_2020.xlsx]原始数据'!$A:$A,ROW(A1)+25),"") | B26: =IFERROR(INDEX('[AQ_2021.xlsx]原始数据'!$A:$A,ROW(A1)+25),"") | C26: =IFERROR(INDEX('[AQ_2022.xlsx]原始数据'!$A:$A,ROW(A1)+25),"") | D26: =IFERROR(INDEX('[AQ_2023.xlsx]原始数据'!$A:$A,ROW(A1)+25),"") | E26: =IFERROR(INDEX('[AQ_2024.xlsx]原始数据'!$A:$A,ROW(A1)+25),"") | G26: =IF(25<=1000,INDEX($A$2:$A$1001,25),IF(25<=2000,INDEX($B$2:$B$1001,-975),IF(25<=3000,INDEX($C$2:$C$1001,-1975),IF(25<=4000,INDEX($D$2:$D$1001,-2975),IF(25<=5000,INDEX($E$2:$E$1001,-3975),"")))))
A27: =IFERROR(INDEX('[AQ_2020.xlsx]原始数据'!$A:$A,ROW(A1)+26),"") | B27: =IFERROR(INDEX('[AQ_2021.xlsx]原始数据'!$A:$A,ROW(A1)+26),"") | C27: =IFERROR(INDEX('[AQ_2022.xlsx]原始数据'!$A:$A,ROW(A1)+26),"") | D27: =IFERROR(INDEX('[AQ_2023.xlsx]原始数据'!$A:$A,ROW(A1)+26),"") | E27: =IFERROR(INDEX('[AQ_2024.xlsx]原始数据'!$A:$A,ROW(A1)+26),"") | G27: =IF(26<=1000,INDEX($A$2:$A$1001,26),IF(26<=2000,INDEX($B$2:$B$1001,-974),IF(26<=3000,INDEX($C$2:$C$1001,-1974),IF(26<=4000,INDEX($D$2:$D$1001,-2974),IF(26<=5000,INDEX($E$2:$E$1001,-3974),"")))))
A28: =IFERROR(INDEX('[AQ_2020.xlsx]原始数据'!$A:$A,ROW(A1)+27),"") | B28: =IFERROR(INDEX('[AQ_2021.xlsx]原始数据'!$A:$A,ROW(A1)+27),"") | C28: =IFERROR(INDEX('[AQ_2022.xlsx]原始数据'!$A:$A,ROW(A1)+27),"") | D28: =IFERROR(INDEX('[AQ_2023.xlsx]原始数据'!$A:$A,ROW(A1)+27),"") | E28: =IFERROR(INDEX('[AQ_2024.xlsx]原始数据'!$A:$A,ROW(A1)+27),"") | G28: =IF(27<=1000,INDEX($A$2:$A$1001,27),IF(27<=2000,INDEX($B$2:$B$1001,-973),IF(27<=3000,INDEX($C$2:$C$1001,-1973),IF(27<=4000,INDEX($D$2:$D$1001,-2973),IF(27<=5000,INDEX($E$2:$E$1001,-3973),"")))))
A29: =IFERROR(INDEX('[AQ_2020.xlsx]原始数据'!$A:$A,ROW(A1)+28),"") | B29: =IFERROR(INDEX('[AQ_2021.xlsx]原始数据'!$A:$A,ROW(A1)+28),"") | C29: =IFERROR(INDEX('[AQ_2022.xlsx]原始数据'!$A:$A,ROW(A1)+28),"") | D29: =IFERROR(INDEX('[AQ_2023.xlsx]原始数据'!$A:$A,ROW(A1)+28),"") | E29: =IFERROR(INDEX('[AQ_2024.xlsx]原始数据'!$A:$A,ROW(A1)+28),"") | G29: =IF(28<=1000,INDEX($A$2:$A$1001,28),IF(28<=2000,INDEX($B$2:$B$1001,-972),IF(28<=3000,INDEX($C$2:$C$1001,-1972),IF(28<=4000,INDEX($D$2:$D$1001,-2972),IF(28<=5000,INDEX($E$2:$E$1001,-3972),"")))))
A30: =IFERROR(INDEX('[AQ_2020.xlsx]原始数据'!$A:$A,ROW(A1)+29),"") | B30: =IFERROR(INDEX('[AQ_2021.xlsx]原始数据'!$A:$A,ROW(A1)+29),"") | C30: =IFERROR(INDEX('[AQ_2022.xlsx]原始数据'!$A:$A,ROW(A1)+29),"") | D30: =IFERROR(INDEX('[AQ_2023.xlsx]原始数据'!$A:$A,ROW(A1)+29),"") | E30: =IFERROR(INDEX('[AQ_2024.xlsx]原始数据'!$A:$A,ROW(A1)+29),"") | G30: =IF(29<=1000,INDEX($A$2:$A$1001,29),IF(29<=2000,INDEX($B$2:$B$1001,-971),IF(29<=3000,INDEX($C$2:$C$1001,-1971),IF(29<=4000,INDEX($D$2:$D$1001,-2971),IF(29<=5000,INDEX($E$2:$E$1001,-3971),"")))))
A31: =IFERROR(INDEX('[AQ_2020.xlsx]原始数据'!$A:$A,ROW(A1)+30),"") | B31: =IFERROR(INDEX('[AQ_2021.xlsx]原始数据'!$A:$A,ROW(A1)+30),"") | C31: =IFERROR(INDEX('[AQ_2022.xlsx]原始数据'!$A:$A,ROW(A1)+30),"") | D31: =IFERROR(INDEX('[AQ_2023.xlsx]原始数据'!$A:$A,ROW(A1)+30),"") | E31: =IFERROR(INDEX('[AQ_2024.xlsx]原始数据'!$A:$A,ROW(A1)+30),"") | G31: =IF(30<=1000,INDEX($A$2:$A$1001,30),IF(30<=2000,INDEX($B$2:$B$1001,-970),IF(30<=3000,INDEX($C$2:$C$1001,-1970),IF(30<=4000,INDEX($D$2:$D$1001,-2970),IF(30<=5000,INDEX($E$2:$E$1001,-3970),"")))))
